2022-04-21 14:24:25 jdbc[7]: exception
org.h2.jdbc.JdbcSQLSyntaxErrorException: Синтаксическая ошибка в выражении SQL "CREATE TABLE IF NOT EXISTS MAZE (\000a  ID_MAZE INT NOT NULL AUTO_INCREMENT,\000a  LENGTH INT NOT NULL\000a  PRIMARY KEY [*](ID_MAZE))"; ожидалось "HASH, CONSTRAINT, COMMENT, UNIQUE, NOT, NULL, CHECK, REFERENCES, AUTO_INCREMENT, ,, )"
Syntax error in SQL statement "CREATE TABLE IF NOT EXISTS MAZE (\000a  ID_MAZE INT NOT NULL AUTO_INCREMENT,\000a  LENGTH INT NOT NULL\000a  PRIMARY KEY [*](ID_MAZE))"; expected "HASH, CONSTRAINT, COMMENT, UNIQUE, NOT, NULL, CHECK, REFERENCES, AUTO_INCREMENT, ,, )"; SQL statement:
CREATE TABLE IF NOT EXISTS MAZE (
  ID_MAZE INT NOT NULL AUTO_INCREMENT,
  LENGTH INT NOT NULL
  PRIMARY KEY (ID_MAZE)) [42001-210]
2022-04-21 14:24:25 jdbc[7]: exception
org.h2.jdbc.JdbcSQLNonTransientException: Savepoint не имеет имени
Savepoint is unnamed [90064-210]
	at org.h2.message.DbException.getJdbcSQLException(DbException.java:573)
	at org.h2.message.DbException.getJdbcSQLException(DbException.java:496)
	at org.h2.message.DbException.get(DbException.java:227)
	at org.h2.message.DbException.get(DbException.java:203)
	at org.h2.message.DbException.get(DbException.java:192)
	at org.h2.jdbc.JdbcSavepoint.getSavepointName(JdbcSavepoint.java:106)
	at com.dci.intellij.dbn.connection.Resources.getSavepointIdentifier(Resources.java:311)
	at com.dci.intellij.dbn.connection.Resources.rollback(Resources.java:151)
	at com.dci.intellij.dbn.connection.Resources.lambda$rollbackSilently$22(Resources.java:145)
	at com.dci.intellij.dbn.common.util.Unsafe.silent(Unsafe.java:18)
	at com.dci.intellij.dbn.connection.Resources.rollbackSilently(Resources.java:145)
	at com.dci.intellij.dbn.connection.jdbc.DBNConnection.withSavepoint(DBNConnection.java:410)
	at com.dci.intellij.dbn.connection.Savepoints.call(Savepoints.java:24)
	at com.dci.intellij.dbn.common.thread.CancellableDatabaseCall.lambda$call$1(CancellableDatabaseCall.java:63)
	at com.dci.intellij.dbn.common.thread.ThreadMonitor.call(ThreadMonitor.java:63)
	at com.dci.intellij.dbn.common.thread.CancellableDatabaseCall.call(CancellableDatabaseCall.java:56)
	at java.base/java.util.concurrent.FutureTask.run(FutureTask.java:264)
	at java.base/java.util.concurrent.ThreadPoolExecutor.runWorker(ThreadPoolExecutor.java:1128)
	at java.base/java.util.concurrent.ThreadPoolExecutor$Worker.run(ThreadPoolExecutor.java:628)
	at com.dci.intellij.dbn.common.thread.ThreadPool.lambda$createThreadFactory$1(ThreadPool.java:39)
	at java.base/java.lang.Thread.run(Thread.java:829)
2022-04-21 14:24:25 jdbc[7]: exception
org.h2.jdbc.JdbcSQLNonTransientException: Savepoint не имеет имени
Savepoint is unnamed [90064-210]
	at org.h2.message.DbException.getJdbcSQLException(DbException.java:573)
	at org.h2.message.DbException.getJdbcSQLException(DbException.java:496)
	at org.h2.message.DbException.get(DbException.java:227)
	at org.h2.message.DbException.get(DbException.java:203)
	at org.h2.message.DbException.get(DbException.java:192)
	at org.h2.jdbc.JdbcSavepoint.getSavepointName(JdbcSavepoint.java:106)
	at com.dci.intellij.dbn.connection.Resources.getSavepointIdentifier(Resources.java:311)
	at com.dci.intellij.dbn.connection.Resources.releaseSavepoint(Resources.java:198)
	at com.dci.intellij.dbn.connection.jdbc.DBNConnection.withSavepoint(DBNConnection.java:413)
	at com.dci.intellij.dbn.connection.Savepoints.call(Savepoints.java:24)
	at com.dci.intellij.dbn.common.thread.CancellableDatabaseCall.lambda$call$1(CancellableDatabaseCall.java:63)
	at com.dci.intellij.dbn.common.thread.ThreadMonitor.call(ThreadMonitor.java:63)
	at com.dci.intellij.dbn.common.thread.CancellableDatabaseCall.call(CancellableDatabaseCall.java:56)
	at java.base/java.util.concurrent.FutureTask.run(FutureTask.java:264)
	at java.base/java.util.concurrent.ThreadPoolExecutor.runWorker(ThreadPoolExecutor.java:1128)
	at java.base/java.util.concurrent.ThreadPoolExecutor$Worker.run(ThreadPoolExecutor.java:628)
	at com.dci.intellij.dbn.common.thread.ThreadPool.lambda$createThreadFactory$1(ThreadPool.java:39)
	at java.base/java.lang.Thread.run(Thread.java:829)
2022-04-21 14:24:25 jdbc[7]: exception
org.h2.jdbc.JdbcSQLNonTransientException: Объект уже закрыт
The object is already closed [90007-210]
2022-04-21 14:24:54 jdbc[7]: exception
org.h2.jdbc.JdbcSQLNonTransientException: Savepoint не имеет имени
Savepoint is unnamed [90064-210]
	at org.h2.message.DbException.getJdbcSQLException(DbException.java:573)
	at org.h2.message.DbException.getJdbcSQLException(DbException.java:496)
	at org.h2.message.DbException.get(DbException.java:227)
	at org.h2.message.DbException.get(DbException.java:203)
	at org.h2.message.DbException.get(DbException.java:192)
	at org.h2.jdbc.JdbcSavepoint.getSavepointName(JdbcSavepoint.java:106)
	at com.dci.intellij.dbn.connection.Resources.getSavepointIdentifier(Resources.java:311)
	at com.dci.intellij.dbn.connection.Resources.releaseSavepoint(Resources.java:198)
	at com.dci.intellij.dbn.connection.jdbc.DBNConnection.withSavepoint(DBNConnection.java:413)
	at com.dci.intellij.dbn.connection.Savepoints.call(Savepoints.java:24)
	at com.dci.intellij.dbn.common.thread.CancellableDatabaseCall.lambda$call$1(CancellableDatabaseCall.java:63)
	at com.dci.intellij.dbn.common.thread.ThreadMonitor.call(ThreadMonitor.java:63)
	at com.dci.intellij.dbn.common.thread.CancellableDatabaseCall.call(CancellableDatabaseCall.java:56)
	at java.base/java.util.concurrent.FutureTask.run(FutureTask.java:264)
	at java.base/java.util.concurrent.ThreadPoolExecutor.runWorker(ThreadPoolExecutor.java:1128)
	at java.base/java.util.concurrent.ThreadPoolExecutor$Worker.run(ThreadPoolExecutor.java:628)
	at com.dci.intellij.dbn.common.thread.ThreadPool.lambda$createThreadFactory$1(ThreadPool.java:39)
	at java.base/java.lang.Thread.run(Thread.java:829)
2022-04-21 14:25:48 jdbc[7]: exception
org.h2.jdbc.JdbcSQLSyntaxErrorException: Синтаксическая ошибка в выражении SQL "CREATE TABLE IF NOT EXISTS CELL (\000a  ID_CELL INT NOT NULL AUTO_INCREMENT,\000a  X INT NOT NULL,\000a  Y INT NOT NULL,\000a  [*]VALUE varchar(255) NOT NULL,\000a  PRIMARY KEY (ID_CELL)\000a  )"; ожидалось "identifier"
Syntax error in SQL statement "CREATE TABLE IF NOT EXISTS CELL (\000a  ID_CELL INT NOT NULL AUTO_INCREMENT,\000a  X INT NOT NULL,\000a  Y INT NOT NULL,\000a  [*]VALUE varchar(255) NOT NULL,\000a  PRIMARY KEY (ID_CELL)\000a  )"; expected "identifier"; SQL statement:
CREATE TABLE IF NOT EXISTS CELL (
  ID_CELL INT NOT NULL AUTO_INCREMENT,
  X INT NOT NULL,
  Y INT NOT NULL,
  VALUE varchar(255) NOT NULL,
  PRIMARY KEY (ID_CELL)
  ) [42001-210]
2022-04-21 14:25:48 jdbc[7]: exception
org.h2.jdbc.JdbcSQLNonTransientException: Savepoint не имеет имени
Savepoint is unnamed [90064-210]
	at org.h2.message.DbException.getJdbcSQLException(DbException.java:573)
	at org.h2.message.DbException.getJdbcSQLException(DbException.java:496)
	at org.h2.message.DbException.get(DbException.java:227)
	at org.h2.message.DbException.get(DbException.java:203)
	at org.h2.message.DbException.get(DbException.java:192)
	at org.h2.jdbc.JdbcSavepoint.getSavepointName(JdbcSavepoint.java:106)
	at com.dci.intellij.dbn.connection.Resources.getSavepointIdentifier(Resources.java:311)
	at com.dci.intellij.dbn.connection.Resources.rollback(Resources.java:151)
	at com.dci.intellij.dbn.connection.Resources.lambda$rollbackSilently$22(Resources.java:145)
	at com.dci.intellij.dbn.common.util.Unsafe.silent(Unsafe.java:18)
	at com.dci.intellij.dbn.connection.Resources.rollbackSilently(Resources.java:145)
	at com.dci.intellij.dbn.connection.jdbc.DBNConnection.withSavepoint(DBNConnection.java:410)
	at com.dci.intellij.dbn.connection.Savepoints.call(Savepoints.java:24)
	at com.dci.intellij.dbn.common.thread.CancellableDatabaseCall.lambda$call$1(CancellableDatabaseCall.java:63)
	at com.dci.intellij.dbn.common.thread.ThreadMonitor.call(ThreadMonitor.java:63)
	at com.dci.intellij.dbn.common.thread.CancellableDatabaseCall.call(CancellableDatabaseCall.java:56)
	at java.base/java.util.concurrent.FutureTask.run(FutureTask.java:264)
	at java.base/java.util.concurrent.ThreadPoolExecutor.runWorker(ThreadPoolExecutor.java:1128)
	at java.base/java.util.concurrent.ThreadPoolExecutor$Worker.run(ThreadPoolExecutor.java:628)
	at com.dci.intellij.dbn.common.thread.ThreadPool.lambda$createThreadFactory$1(ThreadPool.java:39)
	at java.base/java.lang.Thread.run(Thread.java:829)
2022-04-21 14:25:48 jdbc[7]: exception
org.h2.jdbc.JdbcSQLNonTransientException: Savepoint не имеет имени
Savepoint is unnamed [90064-210]
	at org.h2.message.DbException.getJdbcSQLException(DbException.java:573)
	at org.h2.message.DbException.getJdbcSQLException(DbException.java:496)
	at org.h2.message.DbException.get(DbException.java:227)
	at org.h2.message.DbException.get(DbException.java:203)
	at org.h2.message.DbException.get(DbException.java:192)
	at org.h2.jdbc.JdbcSavepoint.getSavepointName(JdbcSavepoint.java:106)
	at com.dci.intellij.dbn.connection.Resources.getSavepointIdentifier(Resources.java:311)
	at com.dci.intellij.dbn.connection.Resources.releaseSavepoint(Resources.java:198)
	at com.dci.intellij.dbn.connection.jdbc.DBNConnection.withSavepoint(DBNConnection.java:413)
	at com.dci.intellij.dbn.connection.Savepoints.call(Savepoints.java:24)
	at com.dci.intellij.dbn.common.thread.CancellableDatabaseCall.lambda$call$1(CancellableDatabaseCall.java:63)
	at com.dci.intellij.dbn.common.thread.ThreadMonitor.call(ThreadMonitor.java:63)
	at com.dci.intellij.dbn.common.thread.CancellableDatabaseCall.call(CancellableDatabaseCall.java:56)
	at java.base/java.util.concurrent.FutureTask.run(FutureTask.java:264)
	at java.base/java.util.concurrent.ThreadPoolExecutor.runWorker(ThreadPoolExecutor.java:1128)
	at java.base/java.util.concurrent.ThreadPoolExecutor$Worker.run(ThreadPoolExecutor.java:628)
	at com.dci.intellij.dbn.common.thread.ThreadPool.lambda$createThreadFactory$1(ThreadPool.java:39)
	at java.base/java.lang.Thread.run(Thread.java:829)
2022-04-21 14:25:48 jdbc[7]: exception
org.h2.jdbc.JdbcSQLNonTransientException: Объект уже закрыт
The object is already closed [90007-210]
2022-04-21 14:25:59 jdbc[7]: exception
org.h2.jdbc.JdbcSQLNonTransientException: Savepoint не имеет имени
Savepoint is unnamed [90064-210]
	at org.h2.message.DbException.getJdbcSQLException(DbException.java:573)
	at org.h2.message.DbException.getJdbcSQLException(DbException.java:496)
	at org.h2.message.DbException.get(DbException.java:227)
	at org.h2.message.DbException.get(DbException.java:203)
	at org.h2.message.DbException.get(DbException.java:192)
	at org.h2.jdbc.JdbcSavepoint.getSavepointName(JdbcSavepoint.java:106)
	at com.dci.intellij.dbn.connection.Resources.getSavepointIdentifier(Resources.java:311)
	at com.dci.intellij.dbn.connection.Resources.releaseSavepoint(Resources.java:198)
	at com.dci.intellij.dbn.connection.jdbc.DBNConnection.withSavepoint(DBNConnection.java:413)
	at com.dci.intellij.dbn.connection.Savepoints.call(Savepoints.java:24)
	at com.dci.intellij.dbn.common.thread.CancellableDatabaseCall.lambda$call$1(CancellableDatabaseCall.java:63)
	at com.dci.intellij.dbn.common.thread.ThreadMonitor.call(ThreadMonitor.java:63)
	at com.dci.intellij.dbn.common.thread.CancellableDatabaseCall.call(CancellableDatabaseCall.java:56)
	at java.base/java.util.concurrent.FutureTask.run(FutureTask.java:264)
	at java.base/java.util.concurrent.ThreadPoolExecutor.runWorker(ThreadPoolExecutor.java:1128)
	at java.base/java.util.concurrent.ThreadPoolExecutor$Worker.run(ThreadPoolExecutor.java:628)
	at com.dci.intellij.dbn.common.thread.ThreadPool.lambda$createThreadFactory$1(ThreadPool.java:39)
	at java.base/java.lang.Thread.run(Thread.java:829)
2022-04-21 14:27:20 jdbc[7]: exception
org.h2.jdbc.JdbcSQLSyntaxErrorException: Таблица "LOCALITY" не найдена
Table "LOCALITY" not found; SQL statement:
CREATE TABLE IF NOT EXISTS MAZE_CELL (
  ID_MAZE INT NOT NULL,
  ID_CELL INT NOT NULL,
   CONSTRAINT fk_ID_MAZE
  FOREIGN KEY (`ID_MAZE`)
  REFERENCES `LOCALITY` (`ID_MAZE`),
  CONSTRAINT fk_ID_CELL
  FOREIGN KEY (`ID_CELL`)
  REFERENCES `CELL` (`ID_CELL`)) [42102-210]
2022-04-21 14:27:20 jdbc[7]: exception
org.h2.jdbc.JdbcSQLNonTransientException: Savepoint не имеет имени
Savepoint is unnamed [90064-210]
	at org.h2.message.DbException.getJdbcSQLException(DbException.java:573)
	at org.h2.message.DbException.getJdbcSQLException(DbException.java:496)
	at org.h2.message.DbException.get(DbException.java:227)
	at org.h2.message.DbException.get(DbException.java:203)
	at org.h2.message.DbException.get(DbException.java:192)
	at org.h2.jdbc.JdbcSavepoint.getSavepointName(JdbcSavepoint.java:106)
	at com.dci.intellij.dbn.connection.Resources.getSavepointIdentifier(Resources.java:311)
	at com.dci.intellij.dbn.connection.Resources.rollback(Resources.java:151)
	at com.dci.intellij.dbn.connection.Resources.lambda$rollbackSilently$22(Resources.java:145)
	at com.dci.intellij.dbn.common.util.Unsafe.silent(Unsafe.java:18)
	at com.dci.intellij.dbn.connection.Resources.rollbackSilently(Resources.java:145)
	at com.dci.intellij.dbn.connection.jdbc.DBNConnection.withSavepoint(DBNConnection.java:410)
	at com.dci.intellij.dbn.connection.Savepoints.call(Savepoints.java:24)
	at com.dci.intellij.dbn.common.thread.CancellableDatabaseCall.lambda$call$1(CancellableDatabaseCall.java:63)
	at com.dci.intellij.dbn.common.thread.ThreadMonitor.call(ThreadMonitor.java:63)
	at com.dci.intellij.dbn.common.thread.CancellableDatabaseCall.call(CancellableDatabaseCall.java:56)
	at java.base/java.util.concurrent.FutureTask.run(FutureTask.java:264)
	at java.base/java.util.concurrent.ThreadPoolExecutor.runWorker(ThreadPoolExecutor.java:1128)
	at java.base/java.util.concurrent.ThreadPoolExecutor$Worker.run(ThreadPoolExecutor.java:628)
	at com.dci.intellij.dbn.common.thread.ThreadPool.lambda$createThreadFactory$1(ThreadPool.java:39)
	at java.base/java.lang.Thread.run(Thread.java:829)
2022-04-21 14:27:20 jdbc[7]: exception
org.h2.jdbc.JdbcSQLNonTransientException: Savepoint не существует: "SYSTEM_SAVEPOINT_4"
Savepoint is invalid: "SYSTEM_SAVEPOINT_4"; SQL statement:
ROLLBACK TO SAVEPOINT SYSTEM_SAVEPOINT_4 [90063-210]
	at org.h2.message.DbException.getJdbcSQLException(DbException.java:573)
	at org.h2.message.DbException.getJdbcSQLException(DbException.java:496)
	at org.h2.message.DbException.get(DbException.java:227)
	at org.h2.message.DbException.get(DbException.java:203)
	at org.h2.engine.SessionLocal.rollbackToSavepoint(SessionLocal.java:1090)
	at org.h2.command.dml.TransactionCommand.update(TransactionCommand.java:59)
	at org.h2.command.CommandContainer.update(CommandContainer.java:174)
	at org.h2.command.Command.executeUpdate(Command.java:252)
	at org.h2.jdbc.JdbcSavepoint.rollback(JdbcSavepoint.java:68)
	at org.h2.jdbc.JdbcConnection.rollback(JdbcConnection.java:958)
	at com.dci.intellij.dbn.connection.jdbc.DBNConnectionBase.rollback(DBNConnectionBase.java:202)
	at com.dci.intellij.dbn.connection.jdbc.DBNConnection.rollback(DBNConnection.java:43)
	at com.dci.intellij.dbn.connection.Resources.lambda$rollback$23(Resources.java:155)
	at com.dci.intellij.dbn.connection.Resources.invokeResourceAction(Resources.java:301)
	at com.dci.intellij.dbn.connection.Resources.invokeResourceAction(Resources.java:286)
	at com.dci.intellij.dbn.connection.Resources.rollback(Resources.java:152)
	at com.dci.intellij.dbn.connection.Resources.lambda$rollbackSilently$22(Resources.java:145)
	at com.dci.intellij.dbn.common.util.Unsafe.silent(Unsafe.java:18)
	at com.dci.intellij.dbn.connection.Resources.rollbackSilently(Resources.java:145)
	at com.dci.intellij.dbn.connection.jdbc.DBNConnection.withSavepoint(DBNConnection.java:410)
	at com.dci.intellij.dbn.connection.Savepoints.call(Savepoints.java:24)
	at com.dci.intellij.dbn.common.thread.CancellableDatabaseCall.lambda$call$1(CancellableDatabaseCall.java:63)
	at com.dci.intellij.dbn.common.thread.ThreadMonitor.call(ThreadMonitor.java:63)
	at com.dci.intellij.dbn.common.thread.CancellableDatabaseCall.call(CancellableDatabaseCall.java:56)
	at java.base/java.util.concurrent.FutureTask.run(FutureTask.java:264)
	at java.base/java.util.concurrent.ThreadPoolExecutor.runWorker(ThreadPoolExecutor.java:1128)
	at java.base/java.util.concurrent.ThreadPoolExecutor$Worker.run(ThreadPoolExecutor.java:628)
	at com.dci.intellij.dbn.common.thread.ThreadPool.lambda$createThreadFactory$1(ThreadPool.java:39)
	at java.base/java.lang.Thread.run(Thread.java:829)
2022-04-21 14:27:20 jdbc[7]: exception
org.h2.jdbc.JdbcSQLNonTransientException: Savepoint не имеет имени
Savepoint is unnamed [90064-210]
	at org.h2.message.DbException.getJdbcSQLException(DbException.java:573)
	at org.h2.message.DbException.getJdbcSQLException(DbException.java:496)
	at org.h2.message.DbException.get(DbException.java:227)
	at org.h2.message.DbException.get(DbException.java:203)
	at org.h2.message.DbException.get(DbException.java:192)
	at org.h2.jdbc.JdbcSavepoint.getSavepointName(JdbcSavepoint.java:106)
	at com.dci.intellij.dbn.connection.Resources.getSavepointIdentifier(Resources.java:311)
	at com.dci.intellij.dbn.connection.Resources.releaseSavepoint(Resources.java:198)
	at com.dci.intellij.dbn.connection.jdbc.DBNConnection.withSavepoint(DBNConnection.java:413)
	at com.dci.intellij.dbn.connection.Savepoints.call(Savepoints.java:24)
	at com.dci.intellij.dbn.common.thread.CancellableDatabaseCall.lambda$call$1(CancellableDatabaseCall.java:63)
	at com.dci.intellij.dbn.common.thread.ThreadMonitor.call(ThreadMonitor.java:63)
	at com.dci.intellij.dbn.common.thread.CancellableDatabaseCall.call(CancellableDatabaseCall.java:56)
	at java.base/java.util.concurrent.FutureTask.run(FutureTask.java:264)
	at java.base/java.util.concurrent.ThreadPoolExecutor.runWorker(ThreadPoolExecutor.java:1128)
	at java.base/java.util.concurrent.ThreadPoolExecutor$Worker.run(ThreadPoolExecutor.java:628)
	at com.dci.intellij.dbn.common.thread.ThreadPool.lambda$createThreadFactory$1(ThreadPool.java:39)
	at java.base/java.lang.Thread.run(Thread.java:829)
2022-04-21 14:27:20 jdbc[7]: exception
org.h2.jdbc.JdbcSQLNonTransientException: Объект уже закрыт
The object is already closed [90007-210]
2022-04-21 14:27:27 jdbc[7]: exception
org.h2.jdbc.JdbcSQLNonTransientException: Savepoint не имеет имени
Savepoint is unnamed [90064-210]
	at org.h2.message.DbException.getJdbcSQLException(DbException.java:573)
	at org.h2.message.DbException.getJdbcSQLException(DbException.java:496)
	at org.h2.message.DbException.get(DbException.java:227)
	at org.h2.message.DbException.get(DbException.java:203)
	at org.h2.message.DbException.get(DbException.java:192)
	at org.h2.jdbc.JdbcSavepoint.getSavepointName(JdbcSavepoint.java:106)
	at com.dci.intellij.dbn.connection.Resources.getSavepointIdentifier(Resources.java:311)
	at com.dci.intellij.dbn.connection.Resources.releaseSavepoint(Resources.java:198)
	at com.dci.intellij.dbn.connection.jdbc.DBNConnection.withSavepoint(DBNConnection.java:413)
	at com.dci.intellij.dbn.connection.Savepoints.call(Savepoints.java:24)
	at com.dci.intellij.dbn.common.thread.CancellableDatabaseCall.lambda$call$1(CancellableDatabaseCall.java:63)
	at com.dci.intellij.dbn.common.thread.ThreadMonitor.call(ThreadMonitor.java:63)
	at com.dci.intellij.dbn.common.thread.CancellableDatabaseCall.call(CancellableDatabaseCall.java:56)
	at java.base/java.util.concurrent.FutureTask.run(FutureTask.java:264)
	at java.base/java.util.concurrent.ThreadPoolExecutor.runWorker(ThreadPoolExecutor.java:1128)
	at java.base/java.util.concurrent.ThreadPoolExecutor$Worker.run(ThreadPoolExecutor.java:628)
	at com.dci.intellij.dbn.common.thread.ThreadPool.lambda$createThreadFactory$1(ThreadPool.java:39)
	at java.base/java.lang.Thread.run(Thread.java:829)
2022-04-22 17:03:58 jdbc[3]: exception
org.h2.jdbc.JdbcSQLSyntaxErrorException: Синтаксическая ошибка в выражении SQL "insert into MAZE\000a(LENGTH)\000avalues ([*]%d);"; ожидалось "), DEFAULT, INTERSECTS, NOT, EXISTS, UNIQUE, INTERSECTS"
Syntax error in SQL statement "insert into MAZE\000a(LENGTH)\000avalues ([*]%d);"; expected "), DEFAULT, INTERSECTS, NOT, EXISTS, UNIQUE, INTERSECTS"; SQL statement:
insert into MAZE
(LENGTH)
values (%d); [42001-210]
2022-04-22 17:05:03 jdbc[3]: exception
org.h2.jdbc.JdbcSQLSyntaxErrorException: Неверное количество столбцов
Column count does not match; SQL statement:
insert into CELL
values (' ',0,0); [21002-210]
	at org.h2.message.DbException.getJdbcSQLException(DbException.java:521)
	at org.h2.message.DbException.getJdbcSQLException(DbException.java:496)
	at org.h2.message.DbException.get(DbException.java:227)
	at org.h2.message.DbException.get(DbException.java:203)
	at org.h2.message.DbException.get(DbException.java:192)
	at org.h2.command.dml.Insert.prepare(Insert.java:295)
	at org.h2.command.Parser.prepareCommand(Parser.java:557)
	at org.h2.engine.SessionLocal.prepareLocal(SessionLocal.java:615)
	at org.h2.engine.SessionLocal.prepareCommand(SessionLocal.java:553)
	at org.h2.jdbc.JdbcConnection.prepareCommand(JdbcConnection.java:1116)
	at org.h2.jdbc.JdbcStatement.executeInternal(JdbcStatement.java:237)
	at org.h2.jdbc.JdbcStatement.execute(JdbcStatement.java:223)
	at stage2.Tasks3.Inquire.createCell(Inquire.java:32)
	at stage2.Tasks3.App.main(App.java:18)
2022-04-22 17:05:35 jdbc[3]: exception
org.h2.jdbc.JdbcSQLSyntaxErrorException: Синтаксическая ошибка в выражении SQL "insert into MAZE_CELL\000avalues (ID_MAZE,ID_CELL)\000a[*]SELECT ID_CELL,ID_MAZE FROM MAZE INNER JOIN MAZE_CELL ON MAZE_CELL.ID_MAZE=MAZE.ID_MAZE INNER JOIN CELL ON CELL.ID_CELL = MAZE_CELL.ID_CELL;"
Syntax error in SQL statement "insert into MAZE_CELL\000avalues (ID_MAZE,ID_CELL)\000a[*]SELECT ID_CELL,ID_MAZE FROM MAZE INNER JOIN MAZE_CELL ON MAZE_CELL.ID_MAZE=MAZE.ID_MAZE INNER JOIN CELL ON CELL.ID_CELL = MAZE_CELL.ID_CELL;"; SQL statement:
insert into MAZE_CELL
values (ID_MAZE,ID_CELL)
SELECT ID_CELL,ID_MAZE FROM MAZE INNER JOIN MAZE_CELL ON MAZE_CELL.ID_MAZE=MAZE.ID_MAZE INNER JOIN CELL ON CELL.ID_CELL = MAZE_CELL.ID_CELL; [42000-210]
2022-04-22 17:07:39 jdbc[3]: exception
org.h2.jdbc.JdbcSQLSyntaxErrorException: Неоднозначное имя столбца "ID_MAZE"
Ambiguous column name "ID_MAZE"; SQL statement:
insert into MAZE_CELL  (ID_MAZE,ID_CELL) SELECT ID_CELL,ID_MAZE FROM MAZE INNER JOIN MAZE_CELL ON MAZE_CELL.ID_MAZE=MAZE.ID_MAZE INNER JOIN CELL ON CELL.ID_CELL = MAZE_CELL.ID_CELL; [90059-210]
	at org.h2.message.DbException.getJdbcSQLException(DbException.java:651)
	at org.h2.message.DbException.getJdbcSQLException(DbException.java:496)
	at org.h2.message.DbException.get(DbException.java:227)
	at org.h2.message.DbException.get(DbException.java:203)
	at org.h2.expression.ExpressionColumn.mapColumn(ExpressionColumn.java:197)
	at org.h2.expression.ExpressionColumn.mapColumns(ExpressionColumn.java:175)
	at org.h2.command.query.Select.mapColumns(Select.java:1546)
	at org.h2.command.query.Select.init(Select.java:1100)
	at org.h2.command.Parser.parseQuery(Parser.java:2583)
	at org.h2.command.Parser.parseInsert(Parser.java:1662)
	at org.h2.command.Parser.parsePrepared(Parser.java:797)
	at org.h2.command.Parser.parse(Parser.java:674)
	at org.h2.command.Parser.parse(Parser.java:644)
	at org.h2.command.Parser.prepareCommand(Parser.java:551)
	at org.h2.engine.SessionLocal.prepareLocal(SessionLocal.java:615)
	at org.h2.engine.SessionLocal.prepareCommand(SessionLocal.java:553)
	at org.h2.jdbc.JdbcConnection.prepareCommand(JdbcConnection.java:1116)
	at org.h2.jdbc.JdbcStatement.executeInternal(JdbcStatement.java:237)
	at org.h2.jdbc.JdbcStatement.execute(JdbcStatement.java:223)
	at com.dci.intellij.dbn.connection.jdbc.DBNStatement.lambda$execute$0(DBNStatement.java:139)
	at com.dci.intellij.dbn.connection.jdbc.DBNStatement.managed(DBNStatement.java:121)
	at com.dci.intellij.dbn.connection.jdbc.DBNStatement.execute(DBNStatement.java:139)
	at com.dci.intellij.dbn.execution.statement.processor.StatementExecutionBasicProcessor$1.execute(StatementExecutionBasicProcessor.java:438)
	at com.dci.intellij.dbn.execution.statement.processor.StatementExecutionBasicProcessor$1.execute(StatementExecutionBasicProcessor.java:434)
	at com.dci.intellij.dbn.common.thread.CancellableDatabaseCall.lambda$call$0(CancellableDatabaseCall.java:65)
	at com.dci.intellij.dbn.connection.jdbc.DBNConnection.withSavepoint(DBNConnection.java:408)
	at com.dci.intellij.dbn.connection.Savepoints.call(Savepoints.java:24)
	at com.dci.intellij.dbn.common.thread.CancellableDatabaseCall.lambda$call$1(CancellableDatabaseCall.java:63)
	at com.dci.intellij.dbn.common.thread.ThreadMonitor.call(ThreadMonitor.java:63)
	at com.dci.intellij.dbn.common.thread.CancellableDatabaseCall.call(CancellableDatabaseCall.java:56)
	at java.base/java.util.concurrent.FutureTask.run(FutureTask.java:264)
	at java.base/java.util.concurrent.ThreadPoolExecutor.runWorker(ThreadPoolExecutor.java:1128)
	at java.base/java.util.concurrent.ThreadPoolExecutor$Worker.run(ThreadPoolExecutor.java:628)
	at com.dci.intellij.dbn.common.thread.ThreadPool.lambda$createThreadFactory$1(ThreadPool.java:39)
	at java.base/java.lang.Thread.run(Thread.java:829)
2022-04-22 17:07:39 jdbc[3]: exception
org.h2.jdbc.JdbcSQLNonTransientException: Savepoint не имеет имени
Savepoint is unnamed [90064-210]
	at org.h2.message.DbException.getJdbcSQLException(DbException.java:573)
	at org.h2.message.DbException.getJdbcSQLException(DbException.java:496)
	at org.h2.message.DbException.get(DbException.java:227)
	at org.h2.message.DbException.get(DbException.java:203)
	at org.h2.message.DbException.get(DbException.java:192)
	at org.h2.jdbc.JdbcSavepoint.getSavepointName(JdbcSavepoint.java:106)
	at com.dci.intellij.dbn.connection.Resources.getSavepointIdentifier(Resources.java:311)
	at com.dci.intellij.dbn.connection.Resources.rollback(Resources.java:151)
	at com.dci.intellij.dbn.connection.Resources.lambda$rollbackSilently$22(Resources.java:145)
	at com.dci.intellij.dbn.common.util.Unsafe.silent(Unsafe.java:18)
	at com.dci.intellij.dbn.connection.Resources.rollbackSilently(Resources.java:145)
	at com.dci.intellij.dbn.connection.jdbc.DBNConnection.withSavepoint(DBNConnection.java:410)
	at com.dci.intellij.dbn.connection.Savepoints.call(Savepoints.java:24)
	at com.dci.intellij.dbn.common.thread.CancellableDatabaseCall.lambda$call$1(CancellableDatabaseCall.java:63)
	at com.dci.intellij.dbn.common.thread.ThreadMonitor.call(ThreadMonitor.java:63)
	at com.dci.intellij.dbn.common.thread.CancellableDatabaseCall.call(CancellableDatabaseCall.java:56)
	at java.base/java.util.concurrent.FutureTask.run(FutureTask.java:264)
	at java.base/java.util.concurrent.ThreadPoolExecutor.runWorker(ThreadPoolExecutor.java:1128)
	at java.base/java.util.concurrent.ThreadPoolExecutor$Worker.run(ThreadPoolExecutor.java:628)
	at com.dci.intellij.dbn.common.thread.ThreadPool.lambda$createThreadFactory$1(ThreadPool.java:39)
	at java.base/java.lang.Thread.run(Thread.java:829)
2022-04-22 17:07:39 jdbc[3]: exception
org.h2.jdbc.JdbcSQLNonTransientException: Savepoint не имеет имени
Savepoint is unnamed [90064-210]
	at org.h2.message.DbException.getJdbcSQLException(DbException.java:573)
	at org.h2.message.DbException.getJdbcSQLException(DbException.java:496)
	at org.h2.message.DbException.get(DbException.java:227)
	at org.h2.message.DbException.get(DbException.java:203)
	at org.h2.message.DbException.get(DbException.java:192)
	at org.h2.jdbc.JdbcSavepoint.getSavepointName(JdbcSavepoint.java:106)
	at com.dci.intellij.dbn.connection.Resources.getSavepointIdentifier(Resources.java:311)
	at com.dci.intellij.dbn.connection.Resources.releaseSavepoint(Resources.java:198)
	at com.dci.intellij.dbn.connection.jdbc.DBNConnection.withSavepoint(DBNConnection.java:413)
	at com.dci.intellij.dbn.connection.Savepoints.call(Savepoints.java:24)
	at com.dci.intellij.dbn.common.thread.CancellableDatabaseCall.lambda$call$1(CancellableDatabaseCall.java:63)
	at com.dci.intellij.dbn.common.thread.ThreadMonitor.call(ThreadMonitor.java:63)
	at com.dci.intellij.dbn.common.thread.CancellableDatabaseCall.call(CancellableDatabaseCall.java:56)
	at java.base/java.util.concurrent.FutureTask.run(FutureTask.java:264)
	at java.base/java.util.concurrent.ThreadPoolExecutor.runWorker(ThreadPoolExecutor.java:1128)
	at java.base/java.util.concurrent.ThreadPoolExecutor$Worker.run(ThreadPoolExecutor.java:628)
	at com.dci.intellij.dbn.common.thread.ThreadPool.lambda$createThreadFactory$1(ThreadPool.java:39)
	at java.base/java.lang.Thread.run(Thread.java:829)
2022-04-22 17:07:39 jdbc[3]: exception
org.h2.jdbc.JdbcSQLNonTransientException: Объект уже закрыт
The object is already closed [90007-210]
2022-04-22 17:08:27 jdbc[3]: exception
org.h2.jdbc.JdbcSQLNonTransientException: Savepoint не имеет имени
Savepoint is unnamed [90064-210]
	at org.h2.message.DbException.getJdbcSQLException(DbException.java:573)
	at org.h2.message.DbException.getJdbcSQLException(DbException.java:496)
	at org.h2.message.DbException.get(DbException.java:227)
	at org.h2.message.DbException.get(DbException.java:203)
	at org.h2.message.DbException.get(DbException.java:192)
	at org.h2.jdbc.JdbcSavepoint.getSavepointName(JdbcSavepoint.java:106)
	at com.dci.intellij.dbn.connection.Resources.getSavepointIdentifier(Resources.java:311)
	at com.dci.intellij.dbn.connection.Resources.releaseSavepoint(Resources.java:198)
	at com.dci.intellij.dbn.connection.jdbc.DBNConnection.withSavepoint(DBNConnection.java:413)
	at com.dci.intellij.dbn.connection.Savepoints.call(Savepoints.java:24)
	at com.dci.intellij.dbn.common.thread.CancellableDatabaseCall.lambda$call$1(CancellableDatabaseCall.java:63)
	at com.dci.intellij.dbn.common.thread.ThreadMonitor.call(ThreadMonitor.java:63)
	at com.dci.intellij.dbn.common.thread.CancellableDatabaseCall.call(CancellableDatabaseCall.java:56)
	at java.base/java.util.concurrent.FutureTask.run(FutureTask.java:264)
	at java.base/java.util.concurrent.ThreadPoolExecutor.runWorker(ThreadPoolExecutor.java:1128)
	at java.base/java.util.concurrent.ThreadPoolExecutor$Worker.run(ThreadPoolExecutor.java:628)
	at com.dci.intellij.dbn.common.thread.ThreadPool.lambda$createThreadFactory$1(ThreadPool.java:39)
	at java.base/java.lang.Thread.run(Thread.java:829)
2022-04-22 17:08:50 jdbc[3]: exception
org.h2.jdbc.JdbcSQLNonTransientException: Savepoint не имеет имени
Savepoint is unnamed [90064-210]
	at org.h2.message.DbException.getJdbcSQLException(DbException.java:573)
	at org.h2.message.DbException.getJdbcSQLException(DbException.java:496)
	at org.h2.message.DbException.get(DbException.java:227)
	at org.h2.message.DbException.get(DbException.java:203)
	at org.h2.message.DbException.get(DbException.java:192)
	at org.h2.jdbc.JdbcSavepoint.getSavepointName(JdbcSavepoint.java:106)
	at com.dci.intellij.dbn.connection.Resources.getSavepointIdentifier(Resources.java:311)
	at com.dci.intellij.dbn.connection.Resources.releaseSavepoint(Resources.java:198)
	at com.dci.intellij.dbn.connection.jdbc.DBNConnection.withSavepoint(DBNConnection.java:413)
	at com.dci.intellij.dbn.connection.Savepoints.call(Savepoints.java:24)
	at com.dci.intellij.dbn.common.thread.CancellableDatabaseCall.lambda$call$1(CancellableDatabaseCall.java:63)
	at com.dci.intellij.dbn.common.thread.ThreadMonitor.call(ThreadMonitor.java:63)
	at com.dci.intellij.dbn.common.thread.CancellableDatabaseCall.call(CancellableDatabaseCall.java:56)
	at java.base/java.util.concurrent.FutureTask.run(FutureTask.java:264)
	at java.base/java.util.concurrent.ThreadPoolExecutor.runWorker(ThreadPoolExecutor.java:1128)
	at java.base/java.util.concurrent.ThreadPoolExecutor$Worker.run(ThreadPoolExecutor.java:628)
	at com.dci.intellij.dbn.common.thread.ThreadPool.lambda$createThreadFactory$1(ThreadPool.java:39)
	at java.base/java.lang.Thread.run(Thread.java:829)
2022-04-22 17:11:20 jdbc[3]: exception
org.h2.jdbc.JdbcSQLNonTransientException: Savepoint не имеет имени
Savepoint is unnamed [90064-210]
	at org.h2.message.DbException.getJdbcSQLException(DbException.java:573)
	at org.h2.message.DbException.getJdbcSQLException(DbException.java:496)
	at org.h2.message.DbException.get(DbException.java:227)
	at org.h2.message.DbException.get(DbException.java:203)
	at org.h2.message.DbException.get(DbException.java:192)
	at org.h2.jdbc.JdbcSavepoint.getSavepointName(JdbcSavepoint.java:106)
	at com.dci.intellij.dbn.connection.Resources.getSavepointIdentifier(Resources.java:311)
	at com.dci.intellij.dbn.connection.Resources.releaseSavepoint(Resources.java:198)
	at com.dci.intellij.dbn.connection.jdbc.DBNConnection.withSavepoint(DBNConnection.java:413)
	at com.dci.intellij.dbn.connection.Savepoints.call(Savepoints.java:24)
	at com.dci.intellij.dbn.common.thread.CancellableDatabaseCall.lambda$call$1(CancellableDatabaseCall.java:63)
	at com.dci.intellij.dbn.common.thread.ThreadMonitor.call(ThreadMonitor.java:63)
	at com.dci.intellij.dbn.common.thread.CancellableDatabaseCall.call(CancellableDatabaseCall.java:56)
	at java.base/java.util.concurrent.FutureTask.run(FutureTask.java:264)
	at java.base/java.util.concurrent.ThreadPoolExecutor.runWorker(ThreadPoolExecutor.java:1128)
	at java.base/java.util.concurrent.ThreadPoolExecutor$Worker.run(ThreadPoolExecutor.java:628)
	at com.dci.intellij.dbn.common.thread.ThreadPool.lambda$createThreadFactory$1(ThreadPool.java:39)
	at java.base/java.lang.Thread.run(Thread.java:829)
2022-04-22 17:11:33 database: flush
org.h2.message.DbException: Внутренняя ошибка: "org.h2.mvstore.MVStoreException: The file is locked: C:/Users/Denis/IdeaProjects/education/Task3/database.mv.db [2.1.210/7]"
General error: "org.h2.mvstore.MVStoreException: The file is locked: C:/Users/Denis/IdeaProjects/education/Task3/database.mv.db [2.1.210/7]" [50000-210]
	at org.h2.message.DbException.get(DbException.java:216)
	at org.h2.message.DbException.convert(DbException.java:414)
	at org.h2.mvstore.db.Store.lambda$new$0(Store.java:120)
	at org.h2.mvstore.MVStore.handleException(MVStore.java:3296)
	at org.h2.mvstore.MVStore.panic(MVStore.java:585)
	at org.h2.mvstore.MVStore.<init>(MVStore.java:461)
	at org.h2.mvstore.MVStore$Builder.open(MVStore.java:4056)
	at org.h2.mvstore.db.Store.<init>(Store.java:129)
	at org.h2.engine.Database.<init>(Database.java:324)
	at org.h2.engine.Engine.openSession(Engine.java:92)
	at org.h2.engine.Engine.openSession(Engine.java:222)
	at org.h2.engine.Engine.createSession(Engine.java:201)
	at org.h2.engine.SessionRemote.connectEmbeddedOrServer(SessionRemote.java:338)
	at org.h2.jdbc.JdbcConnection.<init>(JdbcConnection.java:122)
	at org.h2.Driver.connect(Driver.java:59)
	at java.sql/java.sql.DriverManager.getConnection(DriverManager.java:681)
	at java.sql/java.sql.DriverManager.getConnection(DriverManager.java:229)
	at stage2.Tasks3.DBConnection.getDBConnection(DBConnection.java:11)
	at stage2.Tasks3.App.main(App.java:11)
Caused by: org.h2.jdbc.JdbcSQLNonTransientException: Внутренняя ошибка: "org.h2.mvstore.MVStoreException: The file is locked: C:/Users/Denis/IdeaProjects/education/Task3/database.mv.db [2.1.210/7]"
General error: "org.h2.mvstore.MVStoreException: The file is locked: C:/Users/Denis/IdeaProjects/education/Task3/database.mv.db [2.1.210/7]" [50000-210]
	at org.h2.message.DbException.getJdbcSQLException(DbException.java:573)
	at org.h2.message.DbException.getJdbcSQLException(DbException.java:496)
	... 19 more
Caused by: org.h2.mvstore.MVStoreException: The file is locked: C:/Users/Denis/IdeaProjects/education/Task3/database.mv.db [2.1.210/7]
	at org.h2.mvstore.DataUtils.newMVStoreException(DataUtils.java:1004)
	at org.h2.mvstore.FileStore.open(FileStore.java:163)
	at org.h2.mvstore.MVStore.<init>(MVStore.java:444)
	... 13 more
2022-04-22 17:12:28 jdbc[3]: exception
org.h2.jdbc.JdbcSQLNonTransientException: Savepoint не имеет имени
Savepoint is unnamed [90064-210]
	at org.h2.message.DbException.getJdbcSQLException(DbException.java:573)
	at org.h2.message.DbException.getJdbcSQLException(DbException.java:496)
	at org.h2.message.DbException.get(DbException.java:227)
	at org.h2.message.DbException.get(DbException.java:203)
	at org.h2.message.DbException.get(DbException.java:192)
	at org.h2.jdbc.JdbcSavepoint.getSavepointName(JdbcSavepoint.java:106)
	at com.dci.intellij.dbn.connection.Resources.getSavepointIdentifier(Resources.java:311)
	at com.dci.intellij.dbn.connection.Resources.releaseSavepoint(Resources.java:198)
	at com.dci.intellij.dbn.connection.jdbc.DBNConnection.withSavepoint(DBNConnection.java:413)
	at com.dci.intellij.dbn.connection.Savepoints.call(Savepoints.java:24)
	at com.dci.intellij.dbn.common.thread.CancellableDatabaseCall.lambda$call$1(CancellableDatabaseCall.java:63)
	at com.dci.intellij.dbn.common.thread.ThreadMonitor.call(ThreadMonitor.java:63)
	at com.dci.intellij.dbn.common.thread.CancellableDatabaseCall.call(CancellableDatabaseCall.java:56)
	at java.base/java.util.concurrent.FutureTask.run(FutureTask.java:264)
	at java.base/java.util.concurrent.ThreadPoolExecutor.runWorker(ThreadPoolExecutor.java:1128)
	at java.base/java.util.concurrent.ThreadPoolExecutor$Worker.run(ThreadPoolExecutor.java:628)
	at com.dci.intellij.dbn.common.thread.ThreadPool.lambda$createThreadFactory$1(ThreadPool.java:39)
	at java.base/java.lang.Thread.run(Thread.java:829)
2022-04-22 17:12:39 jdbc[3]: exception
org.h2.jdbc.JdbcSQLNonTransientException: Savepoint не имеет имени
Savepoint is unnamed [90064-210]
	at org.h2.message.DbException.getJdbcSQLException(DbException.java:573)
	at org.h2.message.DbException.getJdbcSQLException(DbException.java:496)
	at org.h2.message.DbException.get(DbException.java:227)
	at org.h2.message.DbException.get(DbException.java:203)
	at org.h2.message.DbException.get(DbException.java:192)
	at org.h2.jdbc.JdbcSavepoint.getSavepointName(JdbcSavepoint.java:106)
	at com.dci.intellij.dbn.connection.Resources.getSavepointIdentifier(Resources.java:311)
	at com.dci.intellij.dbn.connection.Resources.releaseSavepoint(Resources.java:198)
	at com.dci.intellij.dbn.connection.jdbc.DBNConnection.withSavepoint(DBNConnection.java:413)
	at com.dci.intellij.dbn.connection.Savepoints.call(Savepoints.java:24)
	at com.dci.intellij.dbn.common.thread.CancellableDatabaseCall.lambda$call$1(CancellableDatabaseCall.java:63)
	at com.dci.intellij.dbn.common.thread.ThreadMonitor.call(ThreadMonitor.java:63)
	at com.dci.intellij.dbn.common.thread.CancellableDatabaseCall.call(CancellableDatabaseCall.java:56)
	at java.base/java.util.concurrent.FutureTask.run(FutureTask.java:264)
	at java.base/java.util.concurrent.ThreadPoolExecutor.runWorker(ThreadPoolExecutor.java:1128)
	at java.base/java.util.concurrent.ThreadPoolExecutor$Worker.run(ThreadPoolExecutor.java:628)
	at com.dci.intellij.dbn.common.thread.ThreadPool.lambda$createThreadFactory$1(ThreadPool.java:39)
	at java.base/java.lang.Thread.run(Thread.java:829)
2022-04-22 17:13:26 jdbc[3]: exception
org.h2.jdbc.JdbcSQLNonTransientException: Savepoint не имеет имени
Savepoint is unnamed [90064-210]
	at org.h2.message.DbException.getJdbcSQLException(DbException.java:573)
	at org.h2.message.DbException.getJdbcSQLException(DbException.java:496)
	at org.h2.message.DbException.get(DbException.java:227)
	at org.h2.message.DbException.get(DbException.java:203)
	at org.h2.message.DbException.get(DbException.java:192)
	at org.h2.jdbc.JdbcSavepoint.getSavepointName(JdbcSavepoint.java:106)
	at com.dci.intellij.dbn.connection.Resources.getSavepointIdentifier(Resources.java:311)
	at com.dci.intellij.dbn.connection.Resources.releaseSavepoint(Resources.java:198)
	at com.dci.intellij.dbn.connection.jdbc.DBNConnection.withSavepoint(DBNConnection.java:413)
	at com.dci.intellij.dbn.connection.Savepoints.call(Savepoints.java:24)
	at com.dci.intellij.dbn.common.thread.CancellableDatabaseCall.lambda$call$1(CancellableDatabaseCall.java:63)
	at com.dci.intellij.dbn.common.thread.ThreadMonitor.call(ThreadMonitor.java:63)
	at com.dci.intellij.dbn.common.thread.CancellableDatabaseCall.call(CancellableDatabaseCall.java:56)
	at java.base/java.util.concurrent.FutureTask.run(FutureTask.java:264)
	at java.base/java.util.concurrent.ThreadPoolExecutor.runWorker(ThreadPoolExecutor.java:1128)
	at java.base/java.util.concurrent.ThreadPoolExecutor$Worker.run(ThreadPoolExecutor.java:628)
	at com.dci.intellij.dbn.common.thread.ThreadPool.lambda$createThreadFactory$1(ThreadPool.java:39)
	at java.base/java.lang.Thread.run(Thread.java:829)
2022-04-22 17:15:11 database: flush
org.h2.message.DbException: Внутренняя ошибка: "org.h2.mvstore.MVStoreException: The file is locked: C:/Users/Denis/IdeaProjects/education/Task3/database.mv.db [2.1.210/7]"
General error: "org.h2.mvstore.MVStoreException: The file is locked: C:/Users/Denis/IdeaProjects/education/Task3/database.mv.db [2.1.210/7]" [50000-210]
	at org.h2.message.DbException.get(DbException.java:216)
	at org.h2.message.DbException.convert(DbException.java:414)
	at org.h2.mvstore.db.Store.lambda$new$0(Store.java:120)
	at org.h2.mvstore.MVStore.handleException(MVStore.java:3296)
	at org.h2.mvstore.MVStore.panic(MVStore.java:585)
	at org.h2.mvstore.MVStore.<init>(MVStore.java:461)
	at org.h2.mvstore.MVStore$Builder.open(MVStore.java:4056)
	at org.h2.mvstore.db.Store.<init>(Store.java:129)
	at org.h2.engine.Database.<init>(Database.java:324)
	at org.h2.engine.Engine.openSession(Engine.java:92)
	at org.h2.engine.Engine.openSession(Engine.java:222)
	at org.h2.engine.Engine.createSession(Engine.java:201)
	at org.h2.engine.SessionRemote.connectEmbeddedOrServer(SessionRemote.java:338)
	at org.h2.jdbc.JdbcConnection.<init>(JdbcConnection.java:122)
	at org.h2.Driver.connect(Driver.java:59)
	at java.sql/java.sql.DriverManager.getConnection(DriverManager.java:681)
	at java.sql/java.sql.DriverManager.getConnection(DriverManager.java:229)
	at stage2.Tasks3.DBConnection.getDBConnection(DBConnection.java:11)
	at stage2.Tasks3.App.main(App.java:11)
Caused by: org.h2.jdbc.JdbcSQLNonTransientException: Внутренняя ошибка: "org.h2.mvstore.MVStoreException: The file is locked: C:/Users/Denis/IdeaProjects/education/Task3/database.mv.db [2.1.210/7]"
General error: "org.h2.mvstore.MVStoreException: The file is locked: C:/Users/Denis/IdeaProjects/education/Task3/database.mv.db [2.1.210/7]" [50000-210]
	at org.h2.message.DbException.getJdbcSQLException(DbException.java:573)
	at org.h2.message.DbException.getJdbcSQLException(DbException.java:496)
	... 19 more
Caused by: org.h2.mvstore.MVStoreException: The file is locked: C:/Users/Denis/IdeaProjects/education/Task3/database.mv.db [2.1.210/7]
	at org.h2.mvstore.DataUtils.newMVStoreException(DataUtils.java:1004)
	at org.h2.mvstore.FileStore.open(FileStore.java:163)
	at org.h2.mvstore.MVStore.<init>(MVStore.java:444)
	... 13 more
2022-04-23 01:01:59 jdbc[4]: exception
org.h2.jdbc.JdbcSQLNonTransientException: Savepoint не имеет имени
Savepoint is unnamed [90064-210]
	at org.h2.message.DbException.getJdbcSQLException(DbException.java:573)
	at org.h2.message.DbException.getJdbcSQLException(DbException.java:496)
	at org.h2.message.DbException.get(DbException.java:227)
	at org.h2.message.DbException.get(DbException.java:203)
	at org.h2.message.DbException.get(DbException.java:192)
	at org.h2.jdbc.JdbcSavepoint.getSavepointName(JdbcSavepoint.java:106)
	at com.dci.intellij.dbn.connection.Resources.getSavepointIdentifier(Resources.java:311)
	at com.dci.intellij.dbn.connection.Resources.releaseSavepoint(Resources.java:198)
	at com.dci.intellij.dbn.connection.jdbc.DBNConnection.withSavepoint(DBNConnection.java:413)
	at com.dci.intellij.dbn.connection.Savepoints.call(Savepoints.java:24)
	at com.dci.intellij.dbn.common.thread.CancellableDatabaseCall.lambda$call$1(CancellableDatabaseCall.java:63)
	at com.dci.intellij.dbn.common.thread.ThreadMonitor.call(ThreadMonitor.java:63)
	at com.dci.intellij.dbn.common.thread.CancellableDatabaseCall.call(CancellableDatabaseCall.java:56)
	at java.base/java.util.concurrent.FutureTask.run(FutureTask.java:264)
	at java.base/java.util.concurrent.ThreadPoolExecutor.runWorker(ThreadPoolExecutor.java:1128)
	at java.base/java.util.concurrent.ThreadPoolExecutor$Worker.run(ThreadPoolExecutor.java:628)
	at com.dci.intellij.dbn.common.thread.ThreadPool.lambda$createThreadFactory$1(ThreadPool.java:39)
	at java.base/java.lang.Thread.run(Thread.java:829)
2022-04-23 01:02:11 jdbc[4]: exception
org.h2.jdbc.JdbcSQLNonTransientException: Savepoint не имеет имени
Savepoint is unnamed [90064-210]
	at org.h2.message.DbException.getJdbcSQLException(DbException.java:573)
	at org.h2.message.DbException.getJdbcSQLException(DbException.java:496)
	at org.h2.message.DbException.get(DbException.java:227)
	at org.h2.message.DbException.get(DbException.java:203)
	at org.h2.message.DbException.get(DbException.java:192)
	at org.h2.jdbc.JdbcSavepoint.getSavepointName(JdbcSavepoint.java:106)
	at com.dci.intellij.dbn.connection.Resources.getSavepointIdentifier(Resources.java:311)
	at com.dci.intellij.dbn.connection.Resources.releaseSavepoint(Resources.java:198)
	at com.dci.intellij.dbn.connection.jdbc.DBNConnection.withSavepoint(DBNConnection.java:413)
	at com.dci.intellij.dbn.connection.Savepoints.call(Savepoints.java:24)
	at com.dci.intellij.dbn.common.thread.CancellableDatabaseCall.lambda$call$1(CancellableDatabaseCall.java:63)
	at com.dci.intellij.dbn.common.thread.ThreadMonitor.call(ThreadMonitor.java:63)
	at com.dci.intellij.dbn.common.thread.CancellableDatabaseCall.call(CancellableDatabaseCall.java:56)
	at java.base/java.util.concurrent.FutureTask.run(FutureTask.java:264)
	at java.base/java.util.concurrent.ThreadPoolExecutor.runWorker(ThreadPoolExecutor.java:1128)
	at java.base/java.util.concurrent.ThreadPoolExecutor$Worker.run(ThreadPoolExecutor.java:628)
	at com.dci.intellij.dbn.common.thread.ThreadPool.lambda$createThreadFactory$1(ThreadPool.java:39)
	at java.base/java.lang.Thread.run(Thread.java:829)
2022-04-23 01:02:13 jdbc[4]: exception
org.h2.jdbc.JdbcSQLNonTransientException: Savepoint не имеет имени
Savepoint is unnamed [90064-210]
	at org.h2.message.DbException.getJdbcSQLException(DbException.java:573)
	at org.h2.message.DbException.getJdbcSQLException(DbException.java:496)
	at org.h2.message.DbException.get(DbException.java:227)
	at org.h2.message.DbException.get(DbException.java:203)
	at org.h2.message.DbException.get(DbException.java:192)
	at org.h2.jdbc.JdbcSavepoint.getSavepointName(JdbcSavepoint.java:106)
	at com.dci.intellij.dbn.connection.Resources.getSavepointIdentifier(Resources.java:311)
	at com.dci.intellij.dbn.connection.Resources.releaseSavepoint(Resources.java:198)
	at com.dci.intellij.dbn.connection.jdbc.DBNConnection.withSavepoint(DBNConnection.java:413)
	at com.dci.intellij.dbn.connection.Savepoints.call(Savepoints.java:24)
	at com.dci.intellij.dbn.common.thread.CancellableDatabaseCall.lambda$call$1(CancellableDatabaseCall.java:63)
	at com.dci.intellij.dbn.common.thread.ThreadMonitor.call(ThreadMonitor.java:63)
	at com.dci.intellij.dbn.common.thread.CancellableDatabaseCall.call(CancellableDatabaseCall.java:56)
	at java.base/java.util.concurrent.FutureTask.run(FutureTask.java:264)
	at java.base/java.util.concurrent.ThreadPoolExecutor.runWorker(ThreadPoolExecutor.java:1128)
	at java.base/java.util.concurrent.ThreadPoolExecutor$Worker.run(ThreadPoolExecutor.java:628)
	at com.dci.intellij.dbn.common.thread.ThreadPool.lambda$createThreadFactory$1(ThreadPool.java:39)
	at java.base/java.lang.Thread.run(Thread.java:829)
2022-04-23 01:04:18 jdbc[3]: exception
org.h2.jdbc.JdbcSQLNonTransientException: Savepoint не имеет имени
Savepoint is unnamed [90064-210]
	at org.h2.message.DbException.getJdbcSQLException(DbException.java:573)
	at org.h2.message.DbException.getJdbcSQLException(DbException.java:496)
	at org.h2.message.DbException.get(DbException.java:227)
	at org.h2.message.DbException.get(DbException.java:203)
	at org.h2.message.DbException.get(DbException.java:192)
	at org.h2.jdbc.JdbcSavepoint.getSavepointName(JdbcSavepoint.java:106)
	at com.dci.intellij.dbn.connection.Resources.getSavepointIdentifier(Resources.java:311)
	at com.dci.intellij.dbn.connection.Resources.releaseSavepoint(Resources.java:198)
	at com.dci.intellij.dbn.connection.jdbc.DBNConnection.withSavepoint(DBNConnection.java:413)
	at com.dci.intellij.dbn.connection.Savepoints.call(Savepoints.java:24)
	at com.dci.intellij.dbn.common.thread.CancellableDatabaseCall.lambda$call$1(CancellableDatabaseCall.java:63)
	at com.dci.intellij.dbn.common.thread.ThreadMonitor.call(ThreadMonitor.java:63)
	at com.dci.intellij.dbn.common.thread.CancellableDatabaseCall.call(CancellableDatabaseCall.java:56)
	at java.base/java.util.concurrent.FutureTask.run(FutureTask.java:264)
	at java.base/java.util.concurrent.ThreadPoolExecutor.runWorker(ThreadPoolExecutor.java:1128)
	at java.base/java.util.concurrent.ThreadPoolExecutor$Worker.run(ThreadPoolExecutor.java:628)
	at com.dci.intellij.dbn.common.thread.ThreadPool.lambda$createThreadFactory$1(ThreadPool.java:39)
	at java.base/java.lang.Thread.run(Thread.java:829)
2022-04-23 01:04:26 jdbc[3]: exception
org.h2.jdbc.JdbcSQLNonTransientException: Savepoint не имеет имени
Savepoint is unnamed [90064-210]
	at org.h2.message.DbException.getJdbcSQLException(DbException.java:573)
	at org.h2.message.DbException.getJdbcSQLException(DbException.java:496)
	at org.h2.message.DbException.get(DbException.java:227)
	at org.h2.message.DbException.get(DbException.java:203)
	at org.h2.message.DbException.get(DbException.java:192)
	at org.h2.jdbc.JdbcSavepoint.getSavepointName(JdbcSavepoint.java:106)
	at com.dci.intellij.dbn.connection.Resources.getSavepointIdentifier(Resources.java:311)
	at com.dci.intellij.dbn.connection.Resources.releaseSavepoint(Resources.java:198)
	at com.dci.intellij.dbn.connection.jdbc.DBNConnection.withSavepoint(DBNConnection.java:413)
	at com.dci.intellij.dbn.connection.Savepoints.call(Savepoints.java:24)
	at com.dci.intellij.dbn.common.thread.CancellableDatabaseCall.lambda$call$1(CancellableDatabaseCall.java:63)
	at com.dci.intellij.dbn.common.thread.ThreadMonitor.call(ThreadMonitor.java:63)
	at com.dci.intellij.dbn.common.thread.CancellableDatabaseCall.call(CancellableDatabaseCall.java:56)
	at java.base/java.util.concurrent.FutureTask.run(FutureTask.java:264)
	at java.base/java.util.concurrent.ThreadPoolExecutor.runWorker(ThreadPoolExecutor.java:1128)
	at java.base/java.util.concurrent.ThreadPoolExecutor$Worker.run(ThreadPoolExecutor.java:628)
	at com.dci.intellij.dbn.common.thread.ThreadPool.lambda$createThreadFactory$1(ThreadPool.java:39)
	at java.base/java.lang.Thread.run(Thread.java:829)
2022-04-23 01:04:30 jdbc[3]: exception
org.h2.jdbc.JdbcSQLNonTransientException: Savepoint не имеет имени
Savepoint is unnamed [90064-210]
	at org.h2.message.DbException.getJdbcSQLException(DbException.java:573)
	at org.h2.message.DbException.getJdbcSQLException(DbException.java:496)
	at org.h2.message.DbException.get(DbException.java:227)
	at org.h2.message.DbException.get(DbException.java:203)
	at org.h2.message.DbException.get(DbException.java:192)
	at org.h2.jdbc.JdbcSavepoint.getSavepointName(JdbcSavepoint.java:106)
	at com.dci.intellij.dbn.connection.Resources.getSavepointIdentifier(Resources.java:311)
	at com.dci.intellij.dbn.connection.Resources.releaseSavepoint(Resources.java:198)
	at com.dci.intellij.dbn.connection.jdbc.DBNConnection.withSavepoint(DBNConnection.java:413)
	at com.dci.intellij.dbn.connection.Savepoints.call(Savepoints.java:24)
	at com.dci.intellij.dbn.common.thread.CancellableDatabaseCall.lambda$call$1(CancellableDatabaseCall.java:63)
	at com.dci.intellij.dbn.common.thread.ThreadMonitor.call(ThreadMonitor.java:63)
	at com.dci.intellij.dbn.common.thread.CancellableDatabaseCall.call(CancellableDatabaseCall.java:56)
	at java.base/java.util.concurrent.FutureTask.run(FutureTask.java:264)
	at java.base/java.util.concurrent.ThreadPoolExecutor.runWorker(ThreadPoolExecutor.java:1128)
	at java.base/java.util.concurrent.ThreadPoolExecutor$Worker.run(ThreadPoolExecutor.java:628)
	at com.dci.intellij.dbn.common.thread.ThreadPool.lambda$createThreadFactory$1(ThreadPool.java:39)
	at java.base/java.lang.Thread.run(Thread.java:829)
2022-04-23 01:05:07 jdbc[3]: exception
org.h2.jdbc.JdbcSQLNonTransientException: Savepoint не имеет имени
Savepoint is unnamed [90064-210]
	at org.h2.message.DbException.getJdbcSQLException(DbException.java:573)
	at org.h2.message.DbException.getJdbcSQLException(DbException.java:496)
	at org.h2.message.DbException.get(DbException.java:227)
	at org.h2.message.DbException.get(DbException.java:203)
	at org.h2.message.DbException.get(DbException.java:192)
	at org.h2.jdbc.JdbcSavepoint.getSavepointName(JdbcSavepoint.java:106)
	at com.dci.intellij.dbn.connection.Resources.getSavepointIdentifier(Resources.java:311)
	at com.dci.intellij.dbn.connection.Resources.releaseSavepoint(Resources.java:198)
	at com.dci.intellij.dbn.connection.jdbc.DBNConnection.withSavepoint(DBNConnection.java:413)
	at com.dci.intellij.dbn.connection.Savepoints.call(Savepoints.java:24)
	at com.dci.intellij.dbn.common.thread.CancellableDatabaseCall.lambda$call$1(CancellableDatabaseCall.java:63)
	at com.dci.intellij.dbn.common.thread.ThreadMonitor.call(ThreadMonitor.java:63)
	at com.dci.intellij.dbn.common.thread.CancellableDatabaseCall.call(CancellableDatabaseCall.java:56)
	at java.base/java.util.concurrent.FutureTask.run(FutureTask.java:264)
	at java.base/java.util.concurrent.ThreadPoolExecutor.runWorker(ThreadPoolExecutor.java:1128)
	at java.base/java.util.concurrent.ThreadPoolExecutor$Worker.run(ThreadPoolExecutor.java:628)
	at com.dci.intellij.dbn.common.thread.ThreadPool.lambda$createThreadFactory$1(ThreadPool.java:39)
	at java.base/java.lang.Thread.run(Thread.java:829)
2022-04-23 01:05:10 jdbc[3]: exception
org.h2.jdbc.JdbcSQLNonTransientException: Savepoint не имеет имени
Savepoint is unnamed [90064-210]
	at org.h2.message.DbException.getJdbcSQLException(DbException.java:573)
	at org.h2.message.DbException.getJdbcSQLException(DbException.java:496)
	at org.h2.message.DbException.get(DbException.java:227)
	at org.h2.message.DbException.get(DbException.java:203)
	at org.h2.message.DbException.get(DbException.java:192)
	at org.h2.jdbc.JdbcSavepoint.getSavepointName(JdbcSavepoint.java:106)
	at com.dci.intellij.dbn.connection.Resources.getSavepointIdentifier(Resources.java:311)
	at com.dci.intellij.dbn.connection.Resources.releaseSavepoint(Resources.java:198)
	at com.dci.intellij.dbn.connection.jdbc.DBNConnection.withSavepoint(DBNConnection.java:413)
	at com.dci.intellij.dbn.connection.Savepoints.call(Savepoints.java:24)
	at com.dci.intellij.dbn.common.thread.CancellableDatabaseCall.lambda$call$1(CancellableDatabaseCall.java:63)
	at com.dci.intellij.dbn.common.thread.ThreadMonitor.call(ThreadMonitor.java:63)
	at com.dci.intellij.dbn.common.thread.CancellableDatabaseCall.call(CancellableDatabaseCall.java:56)
	at java.base/java.util.concurrent.FutureTask.run(FutureTask.java:264)
	at java.base/java.util.concurrent.ThreadPoolExecutor.runWorker(ThreadPoolExecutor.java:1128)
	at java.base/java.util.concurrent.ThreadPoolExecutor$Worker.run(ThreadPoolExecutor.java:628)
	at com.dci.intellij.dbn.common.thread.ThreadPool.lambda$createThreadFactory$1(ThreadPool.java:39)
	at java.base/java.lang.Thread.run(Thread.java:829)
2022-04-23 01:05:13 jdbc[3]: exception
org.h2.jdbc.JdbcSQLNonTransientException: Savepoint не имеет имени
Savepoint is unnamed [90064-210]
	at org.h2.message.DbException.getJdbcSQLException(DbException.java:573)
	at org.h2.message.DbException.getJdbcSQLException(DbException.java:496)
	at org.h2.message.DbException.get(DbException.java:227)
	at org.h2.message.DbException.get(DbException.java:203)
	at org.h2.message.DbException.get(DbException.java:192)
	at org.h2.jdbc.JdbcSavepoint.getSavepointName(JdbcSavepoint.java:106)
	at com.dci.intellij.dbn.connection.Resources.getSavepointIdentifier(Resources.java:311)
	at com.dci.intellij.dbn.connection.Resources.releaseSavepoint(Resources.java:198)
	at com.dci.intellij.dbn.connection.jdbc.DBNConnection.withSavepoint(DBNConnection.java:413)
	at com.dci.intellij.dbn.connection.Savepoints.call(Savepoints.java:24)
	at com.dci.intellij.dbn.common.thread.CancellableDatabaseCall.lambda$call$1(CancellableDatabaseCall.java:63)
	at com.dci.intellij.dbn.common.thread.ThreadMonitor.call(ThreadMonitor.java:63)
	at com.dci.intellij.dbn.common.thread.CancellableDatabaseCall.call(CancellableDatabaseCall.java:56)
	at java.base/java.util.concurrent.FutureTask.run(FutureTask.java:264)
	at java.base/java.util.concurrent.ThreadPoolExecutor.runWorker(ThreadPoolExecutor.java:1128)
	at java.base/java.util.concurrent.ThreadPoolExecutor$Worker.run(ThreadPoolExecutor.java:628)
	at com.dci.intellij.dbn.common.thread.ThreadPool.lambda$createThreadFactory$1(ThreadPool.java:39)
	at java.base/java.lang.Thread.run(Thread.java:829)
2022-04-23 17:00:58 jdbc[4]: exception
org.h2.jdbc.JdbcSQLNonTransientException: Savepoint не имеет имени
Savepoint is unnamed [90064-210]
	at org.h2.message.DbException.getJdbcSQLException(DbException.java:573)
	at org.h2.message.DbException.getJdbcSQLException(DbException.java:496)
	at org.h2.message.DbException.get(DbException.java:227)
	at org.h2.message.DbException.get(DbException.java:203)
	at org.h2.message.DbException.get(DbException.java:192)
	at org.h2.jdbc.JdbcSavepoint.getSavepointName(JdbcSavepoint.java:106)
	at com.dci.intellij.dbn.connection.Resources.getSavepointIdentifier(Resources.java:311)
	at com.dci.intellij.dbn.connection.Resources.releaseSavepoint(Resources.java:198)
	at com.dci.intellij.dbn.connection.jdbc.DBNConnection.withSavepoint(DBNConnection.java:413)
	at com.dci.intellij.dbn.connection.Savepoints.call(Savepoints.java:24)
	at com.dci.intellij.dbn.common.thread.CancellableDatabaseCall.lambda$call$1(CancellableDatabaseCall.java:63)
	at com.dci.intellij.dbn.common.thread.ThreadMonitor.call(ThreadMonitor.java:63)
	at com.dci.intellij.dbn.common.thread.CancellableDatabaseCall.call(CancellableDatabaseCall.java:56)
	at java.base/java.util.concurrent.FutureTask.run(FutureTask.java:264)
	at java.base/java.util.concurrent.ThreadPoolExecutor.runWorker(ThreadPoolExecutor.java:1128)
	at java.base/java.util.concurrent.ThreadPoolExecutor$Worker.run(ThreadPoolExecutor.java:628)
	at com.dci.intellij.dbn.common.thread.ThreadPool.lambda$createThreadFactory$1(ThreadPool.java:39)
	at java.base/java.lang.Thread.run(Thread.java:829)
2022-04-23 17:01:07 jdbc[4]: exception
org.h2.jdbc.JdbcSQLNonTransientException: Savepoint не имеет имени
Savepoint is unnamed [90064-210]
	at org.h2.message.DbException.getJdbcSQLException(DbException.java:573)
	at org.h2.message.DbException.getJdbcSQLException(DbException.java:496)
	at org.h2.message.DbException.get(DbException.java:227)
	at org.h2.message.DbException.get(DbException.java:203)
	at org.h2.message.DbException.get(DbException.java:192)
	at org.h2.jdbc.JdbcSavepoint.getSavepointName(JdbcSavepoint.java:106)
	at com.dci.intellij.dbn.connection.Resources.getSavepointIdentifier(Resources.java:311)
	at com.dci.intellij.dbn.connection.Resources.releaseSavepoint(Resources.java:198)
	at com.dci.intellij.dbn.connection.jdbc.DBNConnection.withSavepoint(DBNConnection.java:413)
	at com.dci.intellij.dbn.connection.Savepoints.call(Savepoints.java:24)
	at com.dci.intellij.dbn.common.thread.CancellableDatabaseCall.lambda$call$1(CancellableDatabaseCall.java:63)
	at com.dci.intellij.dbn.common.thread.ThreadMonitor.call(ThreadMonitor.java:63)
	at com.dci.intellij.dbn.common.thread.CancellableDatabaseCall.call(CancellableDatabaseCall.java:56)
	at java.base/java.util.concurrent.FutureTask.run(FutureTask.java:264)
	at java.base/java.util.concurrent.ThreadPoolExecutor.runWorker(ThreadPoolExecutor.java:1128)
	at java.base/java.util.concurrent.ThreadPoolExecutor$Worker.run(ThreadPoolExecutor.java:628)
	at com.dci.intellij.dbn.common.thread.ThreadPool.lambda$createThreadFactory$1(ThreadPool.java:39)
	at java.base/java.lang.Thread.run(Thread.java:829)
2022-04-23 17:01:10 jdbc[4]: exception
org.h2.jdbc.JdbcSQLNonTransientException: Savepoint не имеет имени
Savepoint is unnamed [90064-210]
	at org.h2.message.DbException.getJdbcSQLException(DbException.java:573)
	at org.h2.message.DbException.getJdbcSQLException(DbException.java:496)
	at org.h2.message.DbException.get(DbException.java:227)
	at org.h2.message.DbException.get(DbException.java:203)
	at org.h2.message.DbException.get(DbException.java:192)
	at org.h2.jdbc.JdbcSavepoint.getSavepointName(JdbcSavepoint.java:106)
	at com.dci.intellij.dbn.connection.Resources.getSavepointIdentifier(Resources.java:311)
	at com.dci.intellij.dbn.connection.Resources.releaseSavepoint(Resources.java:198)
	at com.dci.intellij.dbn.connection.jdbc.DBNConnection.withSavepoint(DBNConnection.java:413)
	at com.dci.intellij.dbn.connection.Savepoints.call(Savepoints.java:24)
	at com.dci.intellij.dbn.common.thread.CancellableDatabaseCall.lambda$call$1(CancellableDatabaseCall.java:63)
	at com.dci.intellij.dbn.common.thread.ThreadMonitor.call(ThreadMonitor.java:63)
	at com.dci.intellij.dbn.common.thread.CancellableDatabaseCall.call(CancellableDatabaseCall.java:56)
	at java.base/java.util.concurrent.FutureTask.run(FutureTask.java:264)
	at java.base/java.util.concurrent.ThreadPoolExecutor.runWorker(ThreadPoolExecutor.java:1128)
	at java.base/java.util.concurrent.ThreadPoolExecutor$Worker.run(ThreadPoolExecutor.java:628)
	at com.dci.intellij.dbn.common.thread.ThreadPool.lambda$createThreadFactory$1(ThreadPool.java:39)
	at java.base/java.lang.Thread.run(Thread.java:829)
2022-04-23 17:01:13 jdbc[4]: exception
org.h2.jdbc.JdbcSQLNonTransientException: Savepoint не имеет имени
Savepoint is unnamed [90064-210]
	at org.h2.message.DbException.getJdbcSQLException(DbException.java:573)
	at org.h2.message.DbException.getJdbcSQLException(DbException.java:496)
	at org.h2.message.DbException.get(DbException.java:227)
	at org.h2.message.DbException.get(DbException.java:203)
	at org.h2.message.DbException.get(DbException.java:192)
	at org.h2.jdbc.JdbcSavepoint.getSavepointName(JdbcSavepoint.java:106)
	at com.dci.intellij.dbn.connection.Resources.getSavepointIdentifier(Resources.java:311)
	at com.dci.intellij.dbn.connection.Resources.releaseSavepoint(Resources.java:198)
	at com.dci.intellij.dbn.connection.jdbc.DBNConnection.withSavepoint(DBNConnection.java:413)
	at com.dci.intellij.dbn.connection.Savepoints.call(Savepoints.java:24)
	at com.dci.intellij.dbn.common.thread.CancellableDatabaseCall.lambda$call$1(CancellableDatabaseCall.java:63)
	at com.dci.intellij.dbn.common.thread.ThreadMonitor.call(ThreadMonitor.java:63)
	at com.dci.intellij.dbn.common.thread.CancellableDatabaseCall.call(CancellableDatabaseCall.java:56)
	at java.base/java.util.concurrent.FutureTask.run(FutureTask.java:264)
	at java.base/java.util.concurrent.ThreadPoolExecutor.runWorker(ThreadPoolExecutor.java:1128)
	at java.base/java.util.concurrent.ThreadPoolExecutor$Worker.run(ThreadPoolExecutor.java:628)
	at com.dci.intellij.dbn.common.thread.ThreadPool.lambda$createThreadFactory$1(ThreadPool.java:39)
	at java.base/java.lang.Thread.run(Thread.java:829)
2022-04-23 17:01:39 jdbc[4]: exception
org.h2.jdbc.JdbcSQLSyntaxErrorException: Синтаксическая ошибка в выражении SQL "[*]ELECT MAZE_CELL.ID_CELL,MAZE_CELL.ID_MAZE FROM MAZE\000a                INNER JOIN MAZE_CELL ON MAZE_CELL.ID_MAZE=MAZE.ID_MAZE\000a                INNER JOIN CELL ON CELL.ID_CELL = MAZE_CELL.ID_CELL;"; ожидалось "EXPLAIN, EXECUTE"
Syntax error in SQL statement "[*]ELECT MAZE_CELL.ID_CELL,MAZE_CELL.ID_MAZE FROM MAZE\000a                INNER JOIN MAZE_CELL ON MAZE_CELL.ID_MAZE=MAZE.ID_MAZE\000a                INNER JOIN CELL ON CELL.ID_CELL = MAZE_CELL.ID_CELL;"; expected "EXPLAIN, EXECUTE"; SQL statement:
ELECT MAZE_CELL.ID_CELL,MAZE_CELL.ID_MAZE FROM MAZE
                INNER JOIN MAZE_CELL ON MAZE_CELL.ID_MAZE=MAZE.ID_MAZE
                INNER JOIN CELL ON CELL.ID_CELL = MAZE_CELL.ID_CELL; [42001-210]
2022-04-23 17:01:39 jdbc[4]: exception
org.h2.jdbc.JdbcSQLNonTransientException: Savepoint не имеет имени
Savepoint is unnamed [90064-210]
	at org.h2.message.DbException.getJdbcSQLException(DbException.java:573)
	at org.h2.message.DbException.getJdbcSQLException(DbException.java:496)
	at org.h2.message.DbException.get(DbException.java:227)
	at org.h2.message.DbException.get(DbException.java:203)
	at org.h2.message.DbException.get(DbException.java:192)
	at org.h2.jdbc.JdbcSavepoint.getSavepointName(JdbcSavepoint.java:106)
	at com.dci.intellij.dbn.connection.Resources.getSavepointIdentifier(Resources.java:311)
	at com.dci.intellij.dbn.connection.Resources.rollback(Resources.java:151)
	at com.dci.intellij.dbn.connection.Resources.lambda$rollbackSilently$22(Resources.java:145)
	at com.dci.intellij.dbn.common.util.Unsafe.silent(Unsafe.java:18)
	at com.dci.intellij.dbn.connection.Resources.rollbackSilently(Resources.java:145)
	at com.dci.intellij.dbn.connection.jdbc.DBNConnection.withSavepoint(DBNConnection.java:410)
	at com.dci.intellij.dbn.connection.Savepoints.call(Savepoints.java:24)
	at com.dci.intellij.dbn.common.thread.CancellableDatabaseCall.lambda$call$1(CancellableDatabaseCall.java:63)
	at com.dci.intellij.dbn.common.thread.ThreadMonitor.call(ThreadMonitor.java:63)
	at com.dci.intellij.dbn.common.thread.CancellableDatabaseCall.call(CancellableDatabaseCall.java:56)
	at java.base/java.util.concurrent.FutureTask.run(FutureTask.java:264)
	at java.base/java.util.concurrent.ThreadPoolExecutor.runWorker(ThreadPoolExecutor.java:1128)
	at java.base/java.util.concurrent.ThreadPoolExecutor$Worker.run(ThreadPoolExecutor.java:628)
	at com.dci.intellij.dbn.common.thread.ThreadPool.lambda$createThreadFactory$1(ThreadPool.java:39)
	at java.base/java.lang.Thread.run(Thread.java:829)
2022-04-23 17:01:39 jdbc[4]: exception
org.h2.jdbc.JdbcSQLNonTransientException: Savepoint не имеет имени
Savepoint is unnamed [90064-210]
	at org.h2.message.DbException.getJdbcSQLException(DbException.java:573)
	at org.h2.message.DbException.getJdbcSQLException(DbException.java:496)
	at org.h2.message.DbException.get(DbException.java:227)
	at org.h2.message.DbException.get(DbException.java:203)
	at org.h2.message.DbException.get(DbException.java:192)
	at org.h2.jdbc.JdbcSavepoint.getSavepointName(JdbcSavepoint.java:106)
	at com.dci.intellij.dbn.connection.Resources.getSavepointIdentifier(Resources.java:311)
	at com.dci.intellij.dbn.connection.Resources.releaseSavepoint(Resources.java:198)
	at com.dci.intellij.dbn.connection.jdbc.DBNConnection.withSavepoint(DBNConnection.java:413)
	at com.dci.intellij.dbn.connection.Savepoints.call(Savepoints.java:24)
	at com.dci.intellij.dbn.common.thread.CancellableDatabaseCall.lambda$call$1(CancellableDatabaseCall.java:63)
	at com.dci.intellij.dbn.common.thread.ThreadMonitor.call(ThreadMonitor.java:63)
	at com.dci.intellij.dbn.common.thread.CancellableDatabaseCall.call(CancellableDatabaseCall.java:56)
	at java.base/java.util.concurrent.FutureTask.run(FutureTask.java:264)
	at java.base/java.util.concurrent.ThreadPoolExecutor.runWorker(ThreadPoolExecutor.java:1128)
	at java.base/java.util.concurrent.ThreadPoolExecutor$Worker.run(ThreadPoolExecutor.java:628)
	at com.dci.intellij.dbn.common.thread.ThreadPool.lambda$createThreadFactory$1(ThreadPool.java:39)
	at java.base/java.lang.Thread.run(Thread.java:829)
2022-04-23 17:01:39 jdbc[4]: exception
org.h2.jdbc.JdbcSQLNonTransientException: Объект уже закрыт
The object is already closed [90007-210]
2022-04-23 17:01:44 jdbc[4]: exception
org.h2.jdbc.JdbcSQLNonTransientException: Savepoint не имеет имени
Savepoint is unnamed [90064-210]
	at org.h2.message.DbException.getJdbcSQLException(DbException.java:573)
	at org.h2.message.DbException.getJdbcSQLException(DbException.java:496)
	at org.h2.message.DbException.get(DbException.java:227)
	at org.h2.message.DbException.get(DbException.java:203)
	at org.h2.message.DbException.get(DbException.java:192)
	at org.h2.jdbc.JdbcSavepoint.getSavepointName(JdbcSavepoint.java:106)
	at com.dci.intellij.dbn.connection.Resources.getSavepointIdentifier(Resources.java:311)
	at com.dci.intellij.dbn.connection.Resources.releaseSavepoint(Resources.java:198)
	at com.dci.intellij.dbn.connection.jdbc.DBNConnection.withSavepoint(DBNConnection.java:413)
	at com.dci.intellij.dbn.connection.Savepoints.call(Savepoints.java:24)
	at com.dci.intellij.dbn.common.thread.CancellableDatabaseCall.lambda$call$1(CancellableDatabaseCall.java:63)
	at com.dci.intellij.dbn.common.thread.ThreadMonitor.call(ThreadMonitor.java:63)
	at com.dci.intellij.dbn.common.thread.CancellableDatabaseCall.call(CancellableDatabaseCall.java:56)
	at java.base/java.util.concurrent.FutureTask.run(FutureTask.java:264)
	at java.base/java.util.concurrent.ThreadPoolExecutor.runWorker(ThreadPoolExecutor.java:1128)
	at java.base/java.util.concurrent.ThreadPoolExecutor$Worker.run(ThreadPoolExecutor.java:628)
	at com.dci.intellij.dbn.common.thread.ThreadPool.lambda$createThreadFactory$1(ThreadPool.java:39)
	at java.base/java.lang.Thread.run(Thread.java:829)
2022-04-23 17:51:38 jdbc[3]: exception
org.h2.jdbc.JdbcSQLSyntaxErrorException: Неоднозначное имя столбца "ID_MAZE"
Ambiguous column name "ID_MAZE"; SQL statement:
SELECT MAZE_CELL.ID_CELL,MAZE_CELL.ID_MAZE FROM MAZE
                INNER JOIN MAZE ON MAZE_ID_MAZE=MAZE.ID_MAZE
                INNER JOIN CELL ON CELL.ID_MZE = MAZE.ID_CELL; [90059-210]
	at org.h2.message.DbException.getJdbcSQLException(DbException.java:651)
	at org.h2.message.DbException.getJdbcSQLException(DbException.java:496)
	at org.h2.message.DbException.get(DbException.java:227)
	at org.h2.message.DbException.get(DbException.java:203)
	at org.h2.expression.ExpressionColumn.mapColumn(ExpressionColumn.java:197)
	at org.h2.expression.ExpressionColumn.mapColumns(ExpressionColumn.java:175)
	at org.h2.expression.condition.Comparison.mapColumns(Comparison.java:475)
	at org.h2.table.TableFilter$MapColumnsVisitor.accept(TableFilter.java:1246)
	at org.h2.table.TableFilter.visit(TableFilter.java:1189)
	at org.h2.table.TableFilter.addJoin(TableFilter.java:589)
	at org.h2.command.Parser.addJoin(Parser.java:2469)
	at org.h2.command.Parser.readTableReference(Parser.java:2372)
	at org.h2.command.Parser.parseSelectFromPart(Parser.java:2793)
	at org.h2.command.Parser.parseSelect(Parser.java:2900)
	at org.h2.command.Parser.parseQueryPrimary(Parser.java:2783)
	at org.h2.command.Parser.parseQueryTerm(Parser.java:2650)
	at org.h2.command.Parser.parseQueryExpressionBody(Parser.java:2629)
	at org.h2.command.Parser.parseQueryExpressionBodyAndEndOfQuery(Parser.java:2622)
	at org.h2.command.Parser.parseQueryExpression(Parser.java:2615)
	at org.h2.command.Parser.parseQuery(Parser.java:2576)
	at org.h2.command.Parser.parsePrepared(Parser.java:707)
	at org.h2.command.Parser.parse(Parser.java:674)
	at org.h2.command.Parser.parse(Parser.java:644)
	at org.h2.command.Parser.prepareCommand(Parser.java:551)
	at org.h2.engine.SessionLocal.prepareLocal(SessionLocal.java:615)
	at org.h2.engine.SessionLocal.prepareCommand(SessionLocal.java:553)
	at org.h2.jdbc.JdbcConnection.prepareCommand(JdbcConnection.java:1116)
	at org.h2.jdbc.JdbcStatement.executeInternal(JdbcStatement.java:237)
	at org.h2.jdbc.JdbcStatement.execute(JdbcStatement.java:223)
	at com.dci.intellij.dbn.connection.jdbc.DBNStatement.lambda$execute$0(DBNStatement.java:139)
	at com.dci.intellij.dbn.connection.jdbc.DBNStatement.managed(DBNStatement.java:121)
	at com.dci.intellij.dbn.connection.jdbc.DBNStatement.execute(DBNStatement.java:139)
	at com.dci.intellij.dbn.execution.statement.processor.StatementExecutionBasicProcessor$1.execute(StatementExecutionBasicProcessor.java:438)
	at com.dci.intellij.dbn.execution.statement.processor.StatementExecutionBasicProcessor$1.execute(StatementExecutionBasicProcessor.java:434)
	at com.dci.intellij.dbn.common.thread.CancellableDatabaseCall.lambda$call$0(CancellableDatabaseCall.java:65)
	at com.dci.intellij.dbn.connection.jdbc.DBNConnection.withSavepoint(DBNConnection.java:408)
	at com.dci.intellij.dbn.connection.Savepoints.call(Savepoints.java:24)
	at com.dci.intellij.dbn.common.thread.CancellableDatabaseCall.lambda$call$1(CancellableDatabaseCall.java:63)
	at com.dci.intellij.dbn.common.thread.ThreadMonitor.call(ThreadMonitor.java:63)
	at com.dci.intellij.dbn.common.thread.CancellableDatabaseCall.call(CancellableDatabaseCall.java:56)
	at java.base/java.util.concurrent.FutureTask.run(FutureTask.java:264)
	at java.base/java.util.concurrent.ThreadPoolExecutor.runWorker(ThreadPoolExecutor.java:1128)
	at java.base/java.util.concurrent.ThreadPoolExecutor$Worker.run(ThreadPoolExecutor.java:628)
	at com.dci.intellij.dbn.common.thread.ThreadPool.lambda$createThreadFactory$1(ThreadPool.java:39)
	at java.base/java.lang.Thread.run(Thread.java:829)
2022-04-23 17:51:38 jdbc[3]: exception
org.h2.jdbc.JdbcSQLNonTransientException: Savepoint не имеет имени
Savepoint is unnamed [90064-210]
	at org.h2.message.DbException.getJdbcSQLException(DbException.java:573)
	at org.h2.message.DbException.getJdbcSQLException(DbException.java:496)
	at org.h2.message.DbException.get(DbException.java:227)
	at org.h2.message.DbException.get(DbException.java:203)
	at org.h2.message.DbException.get(DbException.java:192)
	at org.h2.jdbc.JdbcSavepoint.getSavepointName(JdbcSavepoint.java:106)
	at com.dci.intellij.dbn.connection.Resources.getSavepointIdentifier(Resources.java:311)
	at com.dci.intellij.dbn.connection.Resources.rollback(Resources.java:151)
	at com.dci.intellij.dbn.connection.Resources.lambda$rollbackSilently$22(Resources.java:145)
	at com.dci.intellij.dbn.common.util.Unsafe.silent(Unsafe.java:18)
	at com.dci.intellij.dbn.connection.Resources.rollbackSilently(Resources.java:145)
	at com.dci.intellij.dbn.connection.jdbc.DBNConnection.withSavepoint(DBNConnection.java:410)
	at com.dci.intellij.dbn.connection.Savepoints.call(Savepoints.java:24)
	at com.dci.intellij.dbn.common.thread.CancellableDatabaseCall.lambda$call$1(CancellableDatabaseCall.java:63)
	at com.dci.intellij.dbn.common.thread.ThreadMonitor.call(ThreadMonitor.java:63)
	at com.dci.intellij.dbn.common.thread.CancellableDatabaseCall.call(CancellableDatabaseCall.java:56)
	at java.base/java.util.concurrent.FutureTask.run(FutureTask.java:264)
	at java.base/java.util.concurrent.ThreadPoolExecutor.runWorker(ThreadPoolExecutor.java:1128)
	at java.base/java.util.concurrent.ThreadPoolExecutor$Worker.run(ThreadPoolExecutor.java:628)
	at com.dci.intellij.dbn.common.thread.ThreadPool.lambda$createThreadFactory$1(ThreadPool.java:39)
	at java.base/java.lang.Thread.run(Thread.java:829)
2022-04-23 17:51:38 jdbc[3]: exception
org.h2.jdbc.JdbcSQLNonTransientException: Savepoint не имеет имени
Savepoint is unnamed [90064-210]
	at org.h2.message.DbException.getJdbcSQLException(DbException.java:573)
	at org.h2.message.DbException.getJdbcSQLException(DbException.java:496)
	at org.h2.message.DbException.get(DbException.java:227)
	at org.h2.message.DbException.get(DbException.java:203)
	at org.h2.message.DbException.get(DbException.java:192)
	at org.h2.jdbc.JdbcSavepoint.getSavepointName(JdbcSavepoint.java:106)
	at com.dci.intellij.dbn.connection.Resources.getSavepointIdentifier(Resources.java:311)
	at com.dci.intellij.dbn.connection.Resources.releaseSavepoint(Resources.java:198)
	at com.dci.intellij.dbn.connection.jdbc.DBNConnection.withSavepoint(DBNConnection.java:413)
	at com.dci.intellij.dbn.connection.Savepoints.call(Savepoints.java:24)
	at com.dci.intellij.dbn.common.thread.CancellableDatabaseCall.lambda$call$1(CancellableDatabaseCall.java:63)
	at com.dci.intellij.dbn.common.thread.ThreadMonitor.call(ThreadMonitor.java:63)
	at com.dci.intellij.dbn.common.thread.CancellableDatabaseCall.call(CancellableDatabaseCall.java:56)
	at java.base/java.util.concurrent.FutureTask.run(FutureTask.java:264)
	at java.base/java.util.concurrent.ThreadPoolExecutor.runWorker(ThreadPoolExecutor.java:1128)
	at java.base/java.util.concurrent.ThreadPoolExecutor$Worker.run(ThreadPoolExecutor.java:628)
	at com.dci.intellij.dbn.common.thread.ThreadPool.lambda$createThreadFactory$1(ThreadPool.java:39)
	at java.base/java.lang.Thread.run(Thread.java:829)
2022-04-23 17:51:38 jdbc[3]: exception
org.h2.jdbc.JdbcSQLNonTransientException: Объект уже закрыт
The object is already closed [90007-210]
2022-04-23 17:51:54 jdbc[3]: exception
org.h2.jdbc.JdbcSQLSyntaxErrorException: Неоднозначное имя столбца "ID_MAZE"
Ambiguous column name "ID_MAZE"; SQL statement:
SELECT MAZE_CELL.ID_CELL,MAZE_CELL.ID_MAZE FROM MAZE
                INNER JOIN MAZE ON MAZE.ID_MAZE=MAZE.ID_MAZE
                INNER JOIN CELL ON CELL.ID_MZE = MAZE.ID_CELL; [90059-210]
	at org.h2.message.DbException.getJdbcSQLException(DbException.java:651)
	at org.h2.message.DbException.getJdbcSQLException(DbException.java:496)
	at org.h2.message.DbException.get(DbException.java:227)
	at org.h2.message.DbException.get(DbException.java:203)
	at org.h2.expression.ExpressionColumn.mapColumn(ExpressionColumn.java:197)
	at org.h2.expression.ExpressionColumn.mapColumns(ExpressionColumn.java:175)
	at org.h2.expression.condition.Comparison.mapColumns(Comparison.java:474)
	at org.h2.table.TableFilter$MapColumnsVisitor.accept(TableFilter.java:1246)
	at org.h2.table.TableFilter.visit(TableFilter.java:1189)
	at org.h2.table.TableFilter.addJoin(TableFilter.java:589)
	at org.h2.command.Parser.addJoin(Parser.java:2469)
	at org.h2.command.Parser.readTableReference(Parser.java:2372)
	at org.h2.command.Parser.parseSelectFromPart(Parser.java:2793)
	at org.h2.command.Parser.parseSelect(Parser.java:2900)
	at org.h2.command.Parser.parseQueryPrimary(Parser.java:2783)
	at org.h2.command.Parser.parseQueryTerm(Parser.java:2650)
	at org.h2.command.Parser.parseQueryExpressionBody(Parser.java:2629)
	at org.h2.command.Parser.parseQueryExpressionBodyAndEndOfQuery(Parser.java:2622)
	at org.h2.command.Parser.parseQueryExpression(Parser.java:2615)
	at org.h2.command.Parser.parseQuery(Parser.java:2576)
	at org.h2.command.Parser.parsePrepared(Parser.java:707)
	at org.h2.command.Parser.parse(Parser.java:674)
	at org.h2.command.Parser.parse(Parser.java:644)
	at org.h2.command.Parser.prepareCommand(Parser.java:551)
	at org.h2.engine.SessionLocal.prepareLocal(SessionLocal.java:615)
	at org.h2.engine.SessionLocal.prepareCommand(SessionLocal.java:553)
	at org.h2.jdbc.JdbcConnection.prepareCommand(JdbcConnection.java:1116)
	at org.h2.jdbc.JdbcStatement.executeInternal(JdbcStatement.java:237)
	at org.h2.jdbc.JdbcStatement.execute(JdbcStatement.java:223)
	at com.dci.intellij.dbn.connection.jdbc.DBNStatement.lambda$execute$0(DBNStatement.java:139)
	at com.dci.intellij.dbn.connection.jdbc.DBNStatement.managed(DBNStatement.java:121)
	at com.dci.intellij.dbn.connection.jdbc.DBNStatement.execute(DBNStatement.java:139)
	at com.dci.intellij.dbn.execution.statement.processor.StatementExecutionBasicProcessor$1.execute(StatementExecutionBasicProcessor.java:438)
	at com.dci.intellij.dbn.execution.statement.processor.StatementExecutionBasicProcessor$1.execute(StatementExecutionBasicProcessor.java:434)
	at com.dci.intellij.dbn.common.thread.CancellableDatabaseCall.lambda$call$0(CancellableDatabaseCall.java:65)
	at com.dci.intellij.dbn.connection.jdbc.DBNConnection.withSavepoint(DBNConnection.java:408)
	at com.dci.intellij.dbn.connection.Savepoints.call(Savepoints.java:24)
	at com.dci.intellij.dbn.common.thread.CancellableDatabaseCall.lambda$call$1(CancellableDatabaseCall.java:63)
	at com.dci.intellij.dbn.common.thread.ThreadMonitor.call(ThreadMonitor.java:63)
	at com.dci.intellij.dbn.common.thread.CancellableDatabaseCall.call(CancellableDatabaseCall.java:56)
	at java.base/java.util.concurrent.FutureTask.run(FutureTask.java:264)
	at java.base/java.util.concurrent.ThreadPoolExecutor.runWorker(ThreadPoolExecutor.java:1128)
	at java.base/java.util.concurrent.ThreadPoolExecutor$Worker.run(ThreadPoolExecutor.java:628)
	at com.dci.intellij.dbn.common.thread.ThreadPool.lambda$createThreadFactory$1(ThreadPool.java:39)
	at java.base/java.lang.Thread.run(Thread.java:829)
2022-04-23 17:51:54 jdbc[3]: exception
org.h2.jdbc.JdbcSQLNonTransientException: Savepoint не имеет имени
Savepoint is unnamed [90064-210]
	at org.h2.message.DbException.getJdbcSQLException(DbException.java:573)
	at org.h2.message.DbException.getJdbcSQLException(DbException.java:496)
	at org.h2.message.DbException.get(DbException.java:227)
	at org.h2.message.DbException.get(DbException.java:203)
	at org.h2.message.DbException.get(DbException.java:192)
	at org.h2.jdbc.JdbcSavepoint.getSavepointName(JdbcSavepoint.java:106)
	at com.dci.intellij.dbn.connection.Resources.getSavepointIdentifier(Resources.java:311)
	at com.dci.intellij.dbn.connection.Resources.rollback(Resources.java:151)
	at com.dci.intellij.dbn.connection.Resources.lambda$rollbackSilently$22(Resources.java:145)
	at com.dci.intellij.dbn.common.util.Unsafe.silent(Unsafe.java:18)
	at com.dci.intellij.dbn.connection.Resources.rollbackSilently(Resources.java:145)
	at com.dci.intellij.dbn.connection.jdbc.DBNConnection.withSavepoint(DBNConnection.java:410)
	at com.dci.intellij.dbn.connection.Savepoints.call(Savepoints.java:24)
	at com.dci.intellij.dbn.common.thread.CancellableDatabaseCall.lambda$call$1(CancellableDatabaseCall.java:63)
	at com.dci.intellij.dbn.common.thread.ThreadMonitor.call(ThreadMonitor.java:63)
	at com.dci.intellij.dbn.common.thread.CancellableDatabaseCall.call(CancellableDatabaseCall.java:56)
	at java.base/java.util.concurrent.FutureTask.run(FutureTask.java:264)
	at java.base/java.util.concurrent.ThreadPoolExecutor.runWorker(ThreadPoolExecutor.java:1128)
	at java.base/java.util.concurrent.ThreadPoolExecutor$Worker.run(ThreadPoolExecutor.java:628)
	at com.dci.intellij.dbn.common.thread.ThreadPool.lambda$createThreadFactory$1(ThreadPool.java:39)
	at java.base/java.lang.Thread.run(Thread.java:829)
2022-04-23 17:51:54 jdbc[3]: exception
org.h2.jdbc.JdbcSQLNonTransientException: Savepoint не имеет имени
Savepoint is unnamed [90064-210]
	at org.h2.message.DbException.getJdbcSQLException(DbException.java:573)
	at org.h2.message.DbException.getJdbcSQLException(DbException.java:496)
	at org.h2.message.DbException.get(DbException.java:227)
	at org.h2.message.DbException.get(DbException.java:203)
	at org.h2.message.DbException.get(DbException.java:192)
	at org.h2.jdbc.JdbcSavepoint.getSavepointName(JdbcSavepoint.java:106)
	at com.dci.intellij.dbn.connection.Resources.getSavepointIdentifier(Resources.java:311)
	at com.dci.intellij.dbn.connection.Resources.releaseSavepoint(Resources.java:198)
	at com.dci.intellij.dbn.connection.jdbc.DBNConnection.withSavepoint(DBNConnection.java:413)
	at com.dci.intellij.dbn.connection.Savepoints.call(Savepoints.java:24)
	at com.dci.intellij.dbn.common.thread.CancellableDatabaseCall.lambda$call$1(CancellableDatabaseCall.java:63)
	at com.dci.intellij.dbn.common.thread.ThreadMonitor.call(ThreadMonitor.java:63)
	at com.dci.intellij.dbn.common.thread.CancellableDatabaseCall.call(CancellableDatabaseCall.java:56)
	at java.base/java.util.concurrent.FutureTask.run(FutureTask.java:264)
	at java.base/java.util.concurrent.ThreadPoolExecutor.runWorker(ThreadPoolExecutor.java:1128)
	at java.base/java.util.concurrent.ThreadPoolExecutor$Worker.run(ThreadPoolExecutor.java:628)
	at com.dci.intellij.dbn.common.thread.ThreadPool.lambda$createThreadFactory$1(ThreadPool.java:39)
	at java.base/java.lang.Thread.run(Thread.java:829)
2022-04-23 17:51:54 jdbc[3]: exception
org.h2.jdbc.JdbcSQLNonTransientException: Объект уже закрыт
The object is already closed [90007-210]
2022-04-23 17:53:07 jdbc[3]: exception
org.h2.jdbc.JdbcSQLSyntaxErrorException: Столбец "CELL.ID_MZE" не найден
Column "CELL.ID_MZE" not found; SQL statement:
SELECT MAZE_CELL.ID_CELL,MAZE_CELL.ID_MAZE FROM MAZE_CELL
                INNER JOIN CELL ON CELL.ID_MZE =MAZE.ID_CELL; [42122-210]
	at org.h2.message.DbException.getJdbcSQLException(DbException.java:521)
	at org.h2.message.DbException.getJdbcSQLException(DbException.java:496)
	at org.h2.message.DbException.get(DbException.java:227)
	at org.h2.message.DbException.get(DbException.java:203)
	at org.h2.expression.ExpressionColumn.getColumnException(ExpressionColumn.java:248)
	at org.h2.expression.ExpressionColumn.optimizeOther(ExpressionColumn.java:230)
	at org.h2.expression.ExpressionColumn.optimize(ExpressionColumn.java:213)
	at org.h2.expression.condition.Comparison.optimize(Comparison.java:139)
	at org.h2.expression.Expression.optimizeCondition(Expression.java:148)
	at org.h2.command.query.Select.prepare(Select.java:1184)
	at org.h2.command.Parser.prepareCommand(Parser.java:557)
	at org.h2.engine.SessionLocal.prepareLocal(SessionLocal.java:615)
	at org.h2.engine.SessionLocal.prepareCommand(SessionLocal.java:553)
	at org.h2.jdbc.JdbcConnection.prepareCommand(JdbcConnection.java:1116)
	at org.h2.jdbc.JdbcStatement.executeInternal(JdbcStatement.java:237)
	at org.h2.jdbc.JdbcStatement.execute(JdbcStatement.java:223)
	at com.dci.intellij.dbn.connection.jdbc.DBNStatement.lambda$execute$0(DBNStatement.java:139)
	at com.dci.intellij.dbn.connection.jdbc.DBNStatement.managed(DBNStatement.java:121)
	at com.dci.intellij.dbn.connection.jdbc.DBNStatement.execute(DBNStatement.java:139)
	at com.dci.intellij.dbn.execution.statement.processor.StatementExecutionBasicProcessor$1.execute(StatementExecutionBasicProcessor.java:438)
	at com.dci.intellij.dbn.execution.statement.processor.StatementExecutionBasicProcessor$1.execute(StatementExecutionBasicProcessor.java:434)
	at com.dci.intellij.dbn.common.thread.CancellableDatabaseCall.lambda$call$0(CancellableDatabaseCall.java:65)
	at com.dci.intellij.dbn.connection.jdbc.DBNConnection.withSavepoint(DBNConnection.java:408)
	at com.dci.intellij.dbn.connection.Savepoints.call(Savepoints.java:24)
	at com.dci.intellij.dbn.common.thread.CancellableDatabaseCall.lambda$call$1(CancellableDatabaseCall.java:63)
	at com.dci.intellij.dbn.common.thread.ThreadMonitor.call(ThreadMonitor.java:63)
	at com.dci.intellij.dbn.common.thread.CancellableDatabaseCall.call(CancellableDatabaseCall.java:56)
	at java.base/java.util.concurrent.FutureTask.run(FutureTask.java:264)
	at java.base/java.util.concurrent.ThreadPoolExecutor.runWorker(ThreadPoolExecutor.java:1128)
	at java.base/java.util.concurrent.ThreadPoolExecutor$Worker.run(ThreadPoolExecutor.java:628)
	at com.dci.intellij.dbn.common.thread.ThreadPool.lambda$createThreadFactory$1(ThreadPool.java:39)
	at java.base/java.lang.Thread.run(Thread.java:829)
2022-04-23 17:53:07 jdbc[3]: exception
org.h2.jdbc.JdbcSQLNonTransientException: Savepoint не имеет имени
Savepoint is unnamed [90064-210]
	at org.h2.message.DbException.getJdbcSQLException(DbException.java:573)
	at org.h2.message.DbException.getJdbcSQLException(DbException.java:496)
	at org.h2.message.DbException.get(DbException.java:227)
	at org.h2.message.DbException.get(DbException.java:203)
	at org.h2.message.DbException.get(DbException.java:192)
	at org.h2.jdbc.JdbcSavepoint.getSavepointName(JdbcSavepoint.java:106)
	at com.dci.intellij.dbn.connection.Resources.getSavepointIdentifier(Resources.java:311)
	at com.dci.intellij.dbn.connection.Resources.rollback(Resources.java:151)
	at com.dci.intellij.dbn.connection.Resources.lambda$rollbackSilently$22(Resources.java:145)
	at com.dci.intellij.dbn.common.util.Unsafe.silent(Unsafe.java:18)
	at com.dci.intellij.dbn.connection.Resources.rollbackSilently(Resources.java:145)
	at com.dci.intellij.dbn.connection.jdbc.DBNConnection.withSavepoint(DBNConnection.java:410)
	at com.dci.intellij.dbn.connection.Savepoints.call(Savepoints.java:24)
	at com.dci.intellij.dbn.common.thread.CancellableDatabaseCall.lambda$call$1(CancellableDatabaseCall.java:63)
	at com.dci.intellij.dbn.common.thread.ThreadMonitor.call(ThreadMonitor.java:63)
	at com.dci.intellij.dbn.common.thread.CancellableDatabaseCall.call(CancellableDatabaseCall.java:56)
	at java.base/java.util.concurrent.FutureTask.run(FutureTask.java:264)
	at java.base/java.util.concurrent.ThreadPoolExecutor.runWorker(ThreadPoolExecutor.java:1128)
	at java.base/java.util.concurrent.ThreadPoolExecutor$Worker.run(ThreadPoolExecutor.java:628)
	at com.dci.intellij.dbn.common.thread.ThreadPool.lambda$createThreadFactory$1(ThreadPool.java:39)
	at java.base/java.lang.Thread.run(Thread.java:829)
2022-04-23 17:53:07 jdbc[3]: exception
org.h2.jdbc.JdbcSQLNonTransientException: Savepoint не имеет имени
Savepoint is unnamed [90064-210]
	at org.h2.message.DbException.getJdbcSQLException(DbException.java:573)
	at org.h2.message.DbException.getJdbcSQLException(DbException.java:496)
	at org.h2.message.DbException.get(DbException.java:227)
	at org.h2.message.DbException.get(DbException.java:203)
	at org.h2.message.DbException.get(DbException.java:192)
	at org.h2.jdbc.JdbcSavepoint.getSavepointName(JdbcSavepoint.java:106)
	at com.dci.intellij.dbn.connection.Resources.getSavepointIdentifier(Resources.java:311)
	at com.dci.intellij.dbn.connection.Resources.releaseSavepoint(Resources.java:198)
	at com.dci.intellij.dbn.connection.jdbc.DBNConnection.withSavepoint(DBNConnection.java:413)
	at com.dci.intellij.dbn.connection.Savepoints.call(Savepoints.java:24)
	at com.dci.intellij.dbn.common.thread.CancellableDatabaseCall.lambda$call$1(CancellableDatabaseCall.java:63)
	at com.dci.intellij.dbn.common.thread.ThreadMonitor.call(ThreadMonitor.java:63)
	at com.dci.intellij.dbn.common.thread.CancellableDatabaseCall.call(CancellableDatabaseCall.java:56)
	at java.base/java.util.concurrent.FutureTask.run(FutureTask.java:264)
	at java.base/java.util.concurrent.ThreadPoolExecutor.runWorker(ThreadPoolExecutor.java:1128)
	at java.base/java.util.concurrent.ThreadPoolExecutor$Worker.run(ThreadPoolExecutor.java:628)
	at com.dci.intellij.dbn.common.thread.ThreadPool.lambda$createThreadFactory$1(ThreadPool.java:39)
	at java.base/java.lang.Thread.run(Thread.java:829)
2022-04-23 17:53:07 jdbc[3]: exception
org.h2.jdbc.JdbcSQLNonTransientException: Объект уже закрыт
The object is already closed [90007-210]
2022-04-23 17:53:30 jdbc[3]: exception
org.h2.jdbc.JdbcSQLSyntaxErrorException: Столбец "CELL.ID_MAZE" не найден
Column "CELL.ID_MAZE" not found; SQL statement:
SELECT MAZE_CELL.ID_CELL,MAZE_CELL.ID_MAZE FROM MAZE_CELL
                INNER JOIN CELL ON CELL.ID_MAZE =MAZE.ID_CELL; [42122-210]
	at org.h2.message.DbException.getJdbcSQLException(DbException.java:521)
	at org.h2.message.DbException.getJdbcSQLException(DbException.java:496)
	at org.h2.message.DbException.get(DbException.java:227)
	at org.h2.message.DbException.get(DbException.java:203)
	at org.h2.expression.ExpressionColumn.getColumnException(ExpressionColumn.java:248)
	at org.h2.expression.ExpressionColumn.optimizeOther(ExpressionColumn.java:230)
	at org.h2.expression.ExpressionColumn.optimize(ExpressionColumn.java:213)
	at org.h2.expression.condition.Comparison.optimize(Comparison.java:139)
	at org.h2.expression.Expression.optimizeCondition(Expression.java:148)
	at org.h2.command.query.Select.prepare(Select.java:1184)
	at org.h2.command.Parser.prepareCommand(Parser.java:557)
	at org.h2.engine.SessionLocal.prepareLocal(SessionLocal.java:615)
	at org.h2.engine.SessionLocal.prepareCommand(SessionLocal.java:553)
	at org.h2.jdbc.JdbcConnection.prepareCommand(JdbcConnection.java:1116)
	at org.h2.jdbc.JdbcStatement.executeInternal(JdbcStatement.java:237)
	at org.h2.jdbc.JdbcStatement.execute(JdbcStatement.java:223)
	at com.dci.intellij.dbn.connection.jdbc.DBNStatement.lambda$execute$0(DBNStatement.java:139)
	at com.dci.intellij.dbn.connection.jdbc.DBNStatement.managed(DBNStatement.java:121)
	at com.dci.intellij.dbn.connection.jdbc.DBNStatement.execute(DBNStatement.java:139)
	at com.dci.intellij.dbn.execution.statement.processor.StatementExecutionBasicProcessor$1.execute(StatementExecutionBasicProcessor.java:438)
	at com.dci.intellij.dbn.execution.statement.processor.StatementExecutionBasicProcessor$1.execute(StatementExecutionBasicProcessor.java:434)
	at com.dci.intellij.dbn.common.thread.CancellableDatabaseCall.lambda$call$0(CancellableDatabaseCall.java:65)
	at com.dci.intellij.dbn.connection.jdbc.DBNConnection.withSavepoint(DBNConnection.java:408)
	at com.dci.intellij.dbn.connection.Savepoints.call(Savepoints.java:24)
	at com.dci.intellij.dbn.common.thread.CancellableDatabaseCall.lambda$call$1(CancellableDatabaseCall.java:63)
	at com.dci.intellij.dbn.common.thread.ThreadMonitor.call(ThreadMonitor.java:63)
	at com.dci.intellij.dbn.common.thread.CancellableDatabaseCall.call(CancellableDatabaseCall.java:56)
	at java.base/java.util.concurrent.FutureTask.run(FutureTask.java:264)
	at java.base/java.util.concurrent.ThreadPoolExecutor.runWorker(ThreadPoolExecutor.java:1128)
	at java.base/java.util.concurrent.ThreadPoolExecutor$Worker.run(ThreadPoolExecutor.java:628)
	at com.dci.intellij.dbn.common.thread.ThreadPool.lambda$createThreadFactory$1(ThreadPool.java:39)
	at java.base/java.lang.Thread.run(Thread.java:829)
2022-04-23 17:53:30 jdbc[3]: exception
org.h2.jdbc.JdbcSQLNonTransientException: Savepoint не имеет имени
Savepoint is unnamed [90064-210]
	at org.h2.message.DbException.getJdbcSQLException(DbException.java:573)
	at org.h2.message.DbException.getJdbcSQLException(DbException.java:496)
	at org.h2.message.DbException.get(DbException.java:227)
	at org.h2.message.DbException.get(DbException.java:203)
	at org.h2.message.DbException.get(DbException.java:192)
	at org.h2.jdbc.JdbcSavepoint.getSavepointName(JdbcSavepoint.java:106)
	at com.dci.intellij.dbn.connection.Resources.getSavepointIdentifier(Resources.java:311)
	at com.dci.intellij.dbn.connection.Resources.rollback(Resources.java:151)
	at com.dci.intellij.dbn.connection.Resources.lambda$rollbackSilently$22(Resources.java:145)
	at com.dci.intellij.dbn.common.util.Unsafe.silent(Unsafe.java:18)
	at com.dci.intellij.dbn.connection.Resources.rollbackSilently(Resources.java:145)
	at com.dci.intellij.dbn.connection.jdbc.DBNConnection.withSavepoint(DBNConnection.java:410)
	at com.dci.intellij.dbn.connection.Savepoints.call(Savepoints.java:24)
	at com.dci.intellij.dbn.common.thread.CancellableDatabaseCall.lambda$call$1(CancellableDatabaseCall.java:63)
	at com.dci.intellij.dbn.common.thread.ThreadMonitor.call(ThreadMonitor.java:63)
	at com.dci.intellij.dbn.common.thread.CancellableDatabaseCall.call(CancellableDatabaseCall.java:56)
	at java.base/java.util.concurrent.FutureTask.run(FutureTask.java:264)
	at java.base/java.util.concurrent.ThreadPoolExecutor.runWorker(ThreadPoolExecutor.java:1128)
	at java.base/java.util.concurrent.ThreadPoolExecutor$Worker.run(ThreadPoolExecutor.java:628)
	at com.dci.intellij.dbn.common.thread.ThreadPool.lambda$createThreadFactory$1(ThreadPool.java:39)
	at java.base/java.lang.Thread.run(Thread.java:829)
2022-04-23 17:53:30 jdbc[3]: exception
org.h2.jdbc.JdbcSQLNonTransientException: Savepoint не имеет имени
Savepoint is unnamed [90064-210]
	at org.h2.message.DbException.getJdbcSQLException(DbException.java:573)
	at org.h2.message.DbException.getJdbcSQLException(DbException.java:496)
	at org.h2.message.DbException.get(DbException.java:227)
	at org.h2.message.DbException.get(DbException.java:203)
	at org.h2.message.DbException.get(DbException.java:192)
	at org.h2.jdbc.JdbcSavepoint.getSavepointName(JdbcSavepoint.java:106)
	at com.dci.intellij.dbn.connection.Resources.getSavepointIdentifier(Resources.java:311)
	at com.dci.intellij.dbn.connection.Resources.releaseSavepoint(Resources.java:198)
	at com.dci.intellij.dbn.connection.jdbc.DBNConnection.withSavepoint(DBNConnection.java:413)
	at com.dci.intellij.dbn.connection.Savepoints.call(Savepoints.java:24)
	at com.dci.intellij.dbn.common.thread.CancellableDatabaseCall.lambda$call$1(CancellableDatabaseCall.java:63)
	at com.dci.intellij.dbn.common.thread.ThreadMonitor.call(ThreadMonitor.java:63)
	at com.dci.intellij.dbn.common.thread.CancellableDatabaseCall.call(CancellableDatabaseCall.java:56)
	at java.base/java.util.concurrent.FutureTask.run(FutureTask.java:264)
	at java.base/java.util.concurrent.ThreadPoolExecutor.runWorker(ThreadPoolExecutor.java:1128)
	at java.base/java.util.concurrent.ThreadPoolExecutor$Worker.run(ThreadPoolExecutor.java:628)
	at com.dci.intellij.dbn.common.thread.ThreadPool.lambda$createThreadFactory$1(ThreadPool.java:39)
	at java.base/java.lang.Thread.run(Thread.java:829)
2022-04-23 17:53:30 jdbc[3]: exception
org.h2.jdbc.JdbcSQLNonTransientException: Объект уже закрыт
The object is already closed [90007-210]
2022-04-23 17:53:48 jdbc[3]: exception
org.h2.jdbc.JdbcSQLSyntaxErrorException: Столбец "MAZE.ID_MAZE" не найден
Column "MAZE.ID_MAZE" not found; SQL statement:
SELECT MAZE_CELL.ID_CELL,MAZE_CELL.ID_MAZE FROM MAZE_CELL
                INNER JOIN CELL ON CELL.ID_CELL =MAZE.ID_MAZE; [42122-210]
	at org.h2.message.DbException.getJdbcSQLException(DbException.java:521)
	at org.h2.message.DbException.getJdbcSQLException(DbException.java:496)
	at org.h2.message.DbException.get(DbException.java:227)
	at org.h2.message.DbException.get(DbException.java:203)
	at org.h2.expression.ExpressionColumn.getColumnException(ExpressionColumn.java:248)
	at org.h2.expression.ExpressionColumn.optimizeOther(ExpressionColumn.java:230)
	at org.h2.expression.ExpressionColumn.optimize(ExpressionColumn.java:213)
	at org.h2.expression.condition.Comparison.optimize(Comparison.java:140)
	at org.h2.expression.Expression.optimizeCondition(Expression.java:148)
	at org.h2.command.query.Select.prepare(Select.java:1184)
	at org.h2.command.Parser.prepareCommand(Parser.java:557)
	at org.h2.engine.SessionLocal.prepareLocal(SessionLocal.java:615)
	at org.h2.engine.SessionLocal.prepareCommand(SessionLocal.java:553)
	at org.h2.jdbc.JdbcConnection.prepareCommand(JdbcConnection.java:1116)
	at org.h2.jdbc.JdbcStatement.executeInternal(JdbcStatement.java:237)
	at org.h2.jdbc.JdbcStatement.execute(JdbcStatement.java:223)
	at com.dci.intellij.dbn.connection.jdbc.DBNStatement.lambda$execute$0(DBNStatement.java:139)
	at com.dci.intellij.dbn.connection.jdbc.DBNStatement.managed(DBNStatement.java:121)
	at com.dci.intellij.dbn.connection.jdbc.DBNStatement.execute(DBNStatement.java:139)
	at com.dci.intellij.dbn.execution.statement.processor.StatementExecutionBasicProcessor$1.execute(StatementExecutionBasicProcessor.java:438)
	at com.dci.intellij.dbn.execution.statement.processor.StatementExecutionBasicProcessor$1.execute(StatementExecutionBasicProcessor.java:434)
	at com.dci.intellij.dbn.common.thread.CancellableDatabaseCall.lambda$call$0(CancellableDatabaseCall.java:65)
	at com.dci.intellij.dbn.connection.jdbc.DBNConnection.withSavepoint(DBNConnection.java:408)
	at com.dci.intellij.dbn.connection.Savepoints.call(Savepoints.java:24)
	at com.dci.intellij.dbn.common.thread.CancellableDatabaseCall.lambda$call$1(CancellableDatabaseCall.java:63)
	at com.dci.intellij.dbn.common.thread.ThreadMonitor.call(ThreadMonitor.java:63)
	at com.dci.intellij.dbn.common.thread.CancellableDatabaseCall.call(CancellableDatabaseCall.java:56)
	at java.base/java.util.concurrent.FutureTask.run(FutureTask.java:264)
	at java.base/java.util.concurrent.ThreadPoolExecutor.runWorker(ThreadPoolExecutor.java:1128)
	at java.base/java.util.concurrent.ThreadPoolExecutor$Worker.run(ThreadPoolExecutor.java:628)
	at com.dci.intellij.dbn.common.thread.ThreadPool.lambda$createThreadFactory$1(ThreadPool.java:39)
	at java.base/java.lang.Thread.run(Thread.java:829)
2022-04-23 17:53:48 jdbc[3]: exception
org.h2.jdbc.JdbcSQLNonTransientException: Savepoint не имеет имени
Savepoint is unnamed [90064-210]
	at org.h2.message.DbException.getJdbcSQLException(DbException.java:573)
	at org.h2.message.DbException.getJdbcSQLException(DbException.java:496)
	at org.h2.message.DbException.get(DbException.java:227)
	at org.h2.message.DbException.get(DbException.java:203)
	at org.h2.message.DbException.get(DbException.java:192)
	at org.h2.jdbc.JdbcSavepoint.getSavepointName(JdbcSavepoint.java:106)
	at com.dci.intellij.dbn.connection.Resources.getSavepointIdentifier(Resources.java:311)
	at com.dci.intellij.dbn.connection.Resources.rollback(Resources.java:151)
	at com.dci.intellij.dbn.connection.Resources.lambda$rollbackSilently$22(Resources.java:145)
	at com.dci.intellij.dbn.common.util.Unsafe.silent(Unsafe.java:18)
	at com.dci.intellij.dbn.connection.Resources.rollbackSilently(Resources.java:145)
	at com.dci.intellij.dbn.connection.jdbc.DBNConnection.withSavepoint(DBNConnection.java:410)
	at com.dci.intellij.dbn.connection.Savepoints.call(Savepoints.java:24)
	at com.dci.intellij.dbn.common.thread.CancellableDatabaseCall.lambda$call$1(CancellableDatabaseCall.java:63)
	at com.dci.intellij.dbn.common.thread.ThreadMonitor.call(ThreadMonitor.java:63)
	at com.dci.intellij.dbn.common.thread.CancellableDatabaseCall.call(CancellableDatabaseCall.java:56)
	at java.base/java.util.concurrent.FutureTask.run(FutureTask.java:264)
	at java.base/java.util.concurrent.ThreadPoolExecutor.runWorker(ThreadPoolExecutor.java:1128)
	at java.base/java.util.concurrent.ThreadPoolExecutor$Worker.run(ThreadPoolExecutor.java:628)
	at com.dci.intellij.dbn.common.thread.ThreadPool.lambda$createThreadFactory$1(ThreadPool.java:39)
	at java.base/java.lang.Thread.run(Thread.java:829)
2022-04-23 17:53:48 jdbc[3]: exception
org.h2.jdbc.JdbcSQLNonTransientException: Savepoint не имеет имени
Savepoint is unnamed [90064-210]
	at org.h2.message.DbException.getJdbcSQLException(DbException.java:573)
	at org.h2.message.DbException.getJdbcSQLException(DbException.java:496)
	at org.h2.message.DbException.get(DbException.java:227)
	at org.h2.message.DbException.get(DbException.java:203)
	at org.h2.message.DbException.get(DbException.java:192)
	at org.h2.jdbc.JdbcSavepoint.getSavepointName(JdbcSavepoint.java:106)
	at com.dci.intellij.dbn.connection.Resources.getSavepointIdentifier(Resources.java:311)
	at com.dci.intellij.dbn.connection.Resources.releaseSavepoint(Resources.java:198)
	at com.dci.intellij.dbn.connection.jdbc.DBNConnection.withSavepoint(DBNConnection.java:413)
	at com.dci.intellij.dbn.connection.Savepoints.call(Savepoints.java:24)
	at com.dci.intellij.dbn.common.thread.CancellableDatabaseCall.lambda$call$1(CancellableDatabaseCall.java:63)
	at com.dci.intellij.dbn.common.thread.ThreadMonitor.call(ThreadMonitor.java:63)
	at com.dci.intellij.dbn.common.thread.CancellableDatabaseCall.call(CancellableDatabaseCall.java:56)
	at java.base/java.util.concurrent.FutureTask.run(FutureTask.java:264)
	at java.base/java.util.concurrent.ThreadPoolExecutor.runWorker(ThreadPoolExecutor.java:1128)
	at java.base/java.util.concurrent.ThreadPoolExecutor$Worker.run(ThreadPoolExecutor.java:628)
	at com.dci.intellij.dbn.common.thread.ThreadPool.lambda$createThreadFactory$1(ThreadPool.java:39)
	at java.base/java.lang.Thread.run(Thread.java:829)
2022-04-23 17:53:48 jdbc[3]: exception
org.h2.jdbc.JdbcSQLNonTransientException: Объект уже закрыт
The object is already closed [90007-210]
2022-04-23 20:14:07 jdbc[3]: exception
org.h2.jdbc.JdbcSQLSyntaxErrorException: Столбец "MAZE.ID_MAZE" не найден
Column "MAZE.ID_MAZE" not found; SQL statement:
SELECT MAZE_CELL.ID_CELL,MAZE_CELL.ID_MAZE FROM MAZE_CELL
                INNER JOIN CELL ON CELL.ID_CELL =MAZE.ID_MAZE; [42122-210]
	at org.h2.message.DbException.getJdbcSQLException(DbException.java:521)
	at org.h2.message.DbException.getJdbcSQLException(DbException.java:496)
	at org.h2.message.DbException.get(DbException.java:227)
	at org.h2.message.DbException.get(DbException.java:203)
	at org.h2.expression.ExpressionColumn.getColumnException(ExpressionColumn.java:248)
	at org.h2.expression.ExpressionColumn.optimizeOther(ExpressionColumn.java:230)
	at org.h2.expression.ExpressionColumn.optimize(ExpressionColumn.java:213)
	at org.h2.expression.condition.Comparison.optimize(Comparison.java:140)
	at org.h2.expression.Expression.optimizeCondition(Expression.java:148)
	at org.h2.command.query.Select.prepare(Select.java:1184)
	at org.h2.command.Parser.prepareCommand(Parser.java:557)
	at org.h2.engine.SessionLocal.prepareLocal(SessionLocal.java:615)
	at org.h2.engine.SessionLocal.prepareCommand(SessionLocal.java:553)
	at org.h2.jdbc.JdbcConnection.prepareCommand(JdbcConnection.java:1116)
	at org.h2.jdbc.JdbcStatement.executeInternal(JdbcStatement.java:237)
	at org.h2.jdbc.JdbcStatement.execute(JdbcStatement.java:223)
	at com.dci.intellij.dbn.connection.jdbc.DBNStatement.lambda$execute$0(DBNStatement.java:139)
	at com.dci.intellij.dbn.connection.jdbc.DBNStatement.managed(DBNStatement.java:121)
	at com.dci.intellij.dbn.connection.jdbc.DBNStatement.execute(DBNStatement.java:139)
	at com.dci.intellij.dbn.execution.statement.processor.StatementExecutionBasicProcessor$1.execute(StatementExecutionBasicProcessor.java:438)
	at com.dci.intellij.dbn.execution.statement.processor.StatementExecutionBasicProcessor$1.execute(StatementExecutionBasicProcessor.java:434)
	at com.dci.intellij.dbn.common.thread.CancellableDatabaseCall.lambda$call$0(CancellableDatabaseCall.java:65)
	at com.dci.intellij.dbn.connection.jdbc.DBNConnection.withSavepoint(DBNConnection.java:408)
	at com.dci.intellij.dbn.connection.Savepoints.call(Savepoints.java:24)
	at com.dci.intellij.dbn.common.thread.CancellableDatabaseCall.lambda$call$1(CancellableDatabaseCall.java:63)
	at com.dci.intellij.dbn.common.thread.ThreadMonitor.call(ThreadMonitor.java:63)
	at com.dci.intellij.dbn.common.thread.CancellableDatabaseCall.call(CancellableDatabaseCall.java:56)
	at java.base/java.util.concurrent.FutureTask.run(FutureTask.java:264)
	at java.base/java.util.concurrent.ThreadPoolExecutor.runWorker(ThreadPoolExecutor.java:1128)
	at java.base/java.util.concurrent.ThreadPoolExecutor$Worker.run(ThreadPoolExecutor.java:628)
	at com.dci.intellij.dbn.common.thread.ThreadPool.lambda$createThreadFactory$1(ThreadPool.java:39)
	at java.base/java.lang.Thread.run(Thread.java:829)
2022-04-23 20:14:07 jdbc[3]: exception
org.h2.jdbc.JdbcSQLNonTransientException: Savepoint не имеет имени
Savepoint is unnamed [90064-210]
	at org.h2.message.DbException.getJdbcSQLException(DbException.java:573)
	at org.h2.message.DbException.getJdbcSQLException(DbException.java:496)
	at org.h2.message.DbException.get(DbException.java:227)
	at org.h2.message.DbException.get(DbException.java:203)
	at org.h2.message.DbException.get(DbException.java:192)
	at org.h2.jdbc.JdbcSavepoint.getSavepointName(JdbcSavepoint.java:106)
	at com.dci.intellij.dbn.connection.Resources.getSavepointIdentifier(Resources.java:311)
	at com.dci.intellij.dbn.connection.Resources.rollback(Resources.java:151)
	at com.dci.intellij.dbn.connection.Resources.lambda$rollbackSilently$22(Resources.java:145)
	at com.dci.intellij.dbn.common.util.Unsafe.silent(Unsafe.java:18)
	at com.dci.intellij.dbn.connection.Resources.rollbackSilently(Resources.java:145)
	at com.dci.intellij.dbn.connection.jdbc.DBNConnection.withSavepoint(DBNConnection.java:410)
	at com.dci.intellij.dbn.connection.Savepoints.call(Savepoints.java:24)
	at com.dci.intellij.dbn.common.thread.CancellableDatabaseCall.lambda$call$1(CancellableDatabaseCall.java:63)
	at com.dci.intellij.dbn.common.thread.ThreadMonitor.call(ThreadMonitor.java:63)
	at com.dci.intellij.dbn.common.thread.CancellableDatabaseCall.call(CancellableDatabaseCall.java:56)
	at java.base/java.util.concurrent.FutureTask.run(FutureTask.java:264)
	at java.base/java.util.concurrent.ThreadPoolExecutor.runWorker(ThreadPoolExecutor.java:1128)
	at java.base/java.util.concurrent.ThreadPoolExecutor$Worker.run(ThreadPoolExecutor.java:628)
	at com.dci.intellij.dbn.common.thread.ThreadPool.lambda$createThreadFactory$1(ThreadPool.java:39)
	at java.base/java.lang.Thread.run(Thread.java:829)
2022-04-23 20:14:07 jdbc[3]: exception
org.h2.jdbc.JdbcSQLNonTransientException: Savepoint не имеет имени
Savepoint is unnamed [90064-210]
	at org.h2.message.DbException.getJdbcSQLException(DbException.java:573)
	at org.h2.message.DbException.getJdbcSQLException(DbException.java:496)
	at org.h2.message.DbException.get(DbException.java:227)
	at org.h2.message.DbException.get(DbException.java:203)
	at org.h2.message.DbException.get(DbException.java:192)
	at org.h2.jdbc.JdbcSavepoint.getSavepointName(JdbcSavepoint.java:106)
	at com.dci.intellij.dbn.connection.Resources.getSavepointIdentifier(Resources.java:311)
	at com.dci.intellij.dbn.connection.Resources.releaseSavepoint(Resources.java:198)
	at com.dci.intellij.dbn.connection.jdbc.DBNConnection.withSavepoint(DBNConnection.java:413)
	at com.dci.intellij.dbn.connection.Savepoints.call(Savepoints.java:24)
	at com.dci.intellij.dbn.common.thread.CancellableDatabaseCall.lambda$call$1(CancellableDatabaseCall.java:63)
	at com.dci.intellij.dbn.common.thread.ThreadMonitor.call(ThreadMonitor.java:63)
	at com.dci.intellij.dbn.common.thread.CancellableDatabaseCall.call(CancellableDatabaseCall.java:56)
	at java.base/java.util.concurrent.FutureTask.run(FutureTask.java:264)
	at java.base/java.util.concurrent.ThreadPoolExecutor.runWorker(ThreadPoolExecutor.java:1128)
	at java.base/java.util.concurrent.ThreadPoolExecutor$Worker.run(ThreadPoolExecutor.java:628)
	at com.dci.intellij.dbn.common.thread.ThreadPool.lambda$createThreadFactory$1(ThreadPool.java:39)
	at java.base/java.lang.Thread.run(Thread.java:829)
2022-04-23 20:14:07 jdbc[3]: exception
org.h2.jdbc.JdbcSQLNonTransientException: Объект уже закрыт
The object is already closed [90007-210]
2022-04-23 20:15:28 jdbc[3]: exception
org.h2.jdbc.JdbcSQLNonTransientException: Savepoint не имеет имени
Savepoint is unnamed [90064-210]
	at org.h2.message.DbException.getJdbcSQLException(DbException.java:573)
	at org.h2.message.DbException.getJdbcSQLException(DbException.java:496)
	at org.h2.message.DbException.get(DbException.java:227)
	at org.h2.message.DbException.get(DbException.java:203)
	at org.h2.message.DbException.get(DbException.java:192)
	at org.h2.jdbc.JdbcSavepoint.getSavepointName(JdbcSavepoint.java:106)
	at com.dci.intellij.dbn.connection.Resources.getSavepointIdentifier(Resources.java:311)
	at com.dci.intellij.dbn.connection.Resources.releaseSavepoint(Resources.java:198)
	at com.dci.intellij.dbn.connection.jdbc.DBNConnection.withSavepoint(DBNConnection.java:413)
	at com.dci.intellij.dbn.connection.Savepoints.call(Savepoints.java:24)
	at com.dci.intellij.dbn.common.thread.CancellableDatabaseCall.lambda$call$1(CancellableDatabaseCall.java:63)
	at com.dci.intellij.dbn.common.thread.ThreadMonitor.call(ThreadMonitor.java:63)
	at com.dci.intellij.dbn.common.thread.CancellableDatabaseCall.call(CancellableDatabaseCall.java:56)
	at java.base/java.util.concurrent.FutureTask.run(FutureTask.java:264)
	at java.base/java.util.concurrent.ThreadPoolExecutor.runWorker(ThreadPoolExecutor.java:1128)
	at java.base/java.util.concurrent.ThreadPoolExecutor$Worker.run(ThreadPoolExecutor.java:628)
	at com.dci.intellij.dbn.common.thread.ThreadPool.lambda$createThreadFactory$1(ThreadPool.java:39)
	at java.base/java.lang.Thread.run(Thread.java:829)
2022-04-23 20:15:32 jdbc[3]: exception
org.h2.jdbc.JdbcSQLNonTransientException: Savepoint не имеет имени
Savepoint is unnamed [90064-210]
	at org.h2.message.DbException.getJdbcSQLException(DbException.java:573)
	at org.h2.message.DbException.getJdbcSQLException(DbException.java:496)
	at org.h2.message.DbException.get(DbException.java:227)
	at org.h2.message.DbException.get(DbException.java:203)
	at org.h2.message.DbException.get(DbException.java:192)
	at org.h2.jdbc.JdbcSavepoint.getSavepointName(JdbcSavepoint.java:106)
	at com.dci.intellij.dbn.connection.Resources.getSavepointIdentifier(Resources.java:311)
	at com.dci.intellij.dbn.connection.Resources.releaseSavepoint(Resources.java:198)
	at com.dci.intellij.dbn.connection.jdbc.DBNConnection.withSavepoint(DBNConnection.java:413)
	at com.dci.intellij.dbn.connection.Savepoints.call(Savepoints.java:24)
	at com.dci.intellij.dbn.common.thread.CancellableDatabaseCall.lambda$call$1(CancellableDatabaseCall.java:63)
	at com.dci.intellij.dbn.common.thread.ThreadMonitor.call(ThreadMonitor.java:63)
	at com.dci.intellij.dbn.common.thread.CancellableDatabaseCall.call(CancellableDatabaseCall.java:56)
	at java.base/java.util.concurrent.FutureTask.run(FutureTask.java:264)
	at java.base/java.util.concurrent.ThreadPoolExecutor.runWorker(ThreadPoolExecutor.java:1128)
	at java.base/java.util.concurrent.ThreadPoolExecutor$Worker.run(ThreadPoolExecutor.java:628)
	at com.dci.intellij.dbn.common.thread.ThreadPool.lambda$createThreadFactory$1(ThreadPool.java:39)
	at java.base/java.lang.Thread.run(Thread.java:829)
2022-04-23 20:40:20 jdbc[3]: exception
org.h2.jdbc.JdbcSQLNonTransientException: Savepoint не имеет имени
Savepoint is unnamed [90064-210]
	at org.h2.message.DbException.getJdbcSQLException(DbException.java:573)
	at org.h2.message.DbException.getJdbcSQLException(DbException.java:496)
	at org.h2.message.DbException.get(DbException.java:227)
	at org.h2.message.DbException.get(DbException.java:203)
	at org.h2.message.DbException.get(DbException.java:192)
	at org.h2.jdbc.JdbcSavepoint.getSavepointName(JdbcSavepoint.java:106)
	at com.dci.intellij.dbn.connection.Resources.getSavepointIdentifier(Resources.java:311)
	at com.dci.intellij.dbn.connection.Resources.releaseSavepoint(Resources.java:198)
	at com.dci.intellij.dbn.connection.jdbc.DBNConnection.withSavepoint(DBNConnection.java:413)
	at com.dci.intellij.dbn.connection.Savepoints.call(Savepoints.java:24)
	at com.dci.intellij.dbn.common.thread.CancellableDatabaseCall.lambda$call$1(CancellableDatabaseCall.java:63)
	at com.dci.intellij.dbn.common.thread.ThreadMonitor.call(ThreadMonitor.java:63)
	at com.dci.intellij.dbn.common.thread.CancellableDatabaseCall.call(CancellableDatabaseCall.java:56)
	at java.base/java.util.concurrent.FutureTask.run(FutureTask.java:264)
	at java.base/java.util.concurrent.ThreadPoolExecutor.runWorker(ThreadPoolExecutor.java:1128)
	at java.base/java.util.concurrent.ThreadPoolExecutor$Worker.run(ThreadPoolExecutor.java:628)
	at com.dci.intellij.dbn.common.thread.ThreadPool.lambda$createThreadFactory$1(ThreadPool.java:39)
	at java.base/java.lang.Thread.run(Thread.java:829)
2022-04-23 20:40:44 jdbc[3]: exception
org.h2.jdbc.JdbcSQLNonTransientException: Savepoint не имеет имени
Savepoint is unnamed [90064-210]
	at org.h2.message.DbException.getJdbcSQLException(DbException.java:573)
	at org.h2.message.DbException.getJdbcSQLException(DbException.java:496)
	at org.h2.message.DbException.get(DbException.java:227)
	at org.h2.message.DbException.get(DbException.java:203)
	at org.h2.message.DbException.get(DbException.java:192)
	at org.h2.jdbc.JdbcSavepoint.getSavepointName(JdbcSavepoint.java:106)
	at com.dci.intellij.dbn.connection.Resources.getSavepointIdentifier(Resources.java:311)
	at com.dci.intellij.dbn.connection.Resources.releaseSavepoint(Resources.java:198)
	at com.dci.intellij.dbn.connection.jdbc.DBNConnection.withSavepoint(DBNConnection.java:413)
	at com.dci.intellij.dbn.connection.Savepoints.call(Savepoints.java:24)
	at com.dci.intellij.dbn.common.thread.CancellableDatabaseCall.lambda$call$1(CancellableDatabaseCall.java:63)
	at com.dci.intellij.dbn.common.thread.ThreadMonitor.call(ThreadMonitor.java:63)
	at com.dci.intellij.dbn.common.thread.CancellableDatabaseCall.call(CancellableDatabaseCall.java:56)
	at java.base/java.util.concurrent.FutureTask.run(FutureTask.java:264)
	at java.base/java.util.concurrent.ThreadPoolExecutor.runWorker(ThreadPoolExecutor.java:1128)
	at java.base/java.util.concurrent.ThreadPoolExecutor$Worker.run(ThreadPoolExecutor.java:628)
	at com.dci.intellij.dbn.common.thread.ThreadPool.lambda$createThreadFactory$1(ThreadPool.java:39)
	at java.base/java.lang.Thread.run(Thread.java:829)
2022-04-23 20:41:03 jdbc[3]: exception
org.h2.jdbc.JdbcSQLNonTransientException: Savepoint не имеет имени
Savepoint is unnamed [90064-210]
	at org.h2.message.DbException.getJdbcSQLException(DbException.java:573)
	at org.h2.message.DbException.getJdbcSQLException(DbException.java:496)
	at org.h2.message.DbException.get(DbException.java:227)
	at org.h2.message.DbException.get(DbException.java:203)
	at org.h2.message.DbException.get(DbException.java:192)
	at org.h2.jdbc.JdbcSavepoint.getSavepointName(JdbcSavepoint.java:106)
	at com.dci.intellij.dbn.connection.Resources.getSavepointIdentifier(Resources.java:311)
	at com.dci.intellij.dbn.connection.Resources.releaseSavepoint(Resources.java:198)
	at com.dci.intellij.dbn.connection.jdbc.DBNConnection.withSavepoint(DBNConnection.java:413)
	at com.dci.intellij.dbn.connection.Savepoints.call(Savepoints.java:24)
	at com.dci.intellij.dbn.common.thread.CancellableDatabaseCall.lambda$call$1(CancellableDatabaseCall.java:63)
	at com.dci.intellij.dbn.common.thread.ThreadMonitor.call(ThreadMonitor.java:63)
	at com.dci.intellij.dbn.common.thread.CancellableDatabaseCall.call(CancellableDatabaseCall.java:56)
	at java.base/java.util.concurrent.FutureTask.run(FutureTask.java:264)
	at java.base/java.util.concurrent.ThreadPoolExecutor.runWorker(ThreadPoolExecutor.java:1128)
	at java.base/java.util.concurrent.ThreadPoolExecutor$Worker.run(ThreadPoolExecutor.java:628)
	at com.dci.intellij.dbn.common.thread.ThreadPool.lambda$createThreadFactory$1(ThreadPool.java:39)
	at java.base/java.lang.Thread.run(Thread.java:829)
2022-04-23 20:41:06 jdbc[3]: exception
org.h2.jdbc.JdbcSQLNonTransientException: Savepoint не имеет имени
Savepoint is unnamed [90064-210]
	at org.h2.message.DbException.getJdbcSQLException(DbException.java:573)
	at org.h2.message.DbException.getJdbcSQLException(DbException.java:496)
	at org.h2.message.DbException.get(DbException.java:227)
	at org.h2.message.DbException.get(DbException.java:203)
	at org.h2.message.DbException.get(DbException.java:192)
	at org.h2.jdbc.JdbcSavepoint.getSavepointName(JdbcSavepoint.java:106)
	at com.dci.intellij.dbn.connection.Resources.getSavepointIdentifier(Resources.java:311)
	at com.dci.intellij.dbn.connection.Resources.releaseSavepoint(Resources.java:198)
	at com.dci.intellij.dbn.connection.jdbc.DBNConnection.withSavepoint(DBNConnection.java:413)
	at com.dci.intellij.dbn.connection.Savepoints.call(Savepoints.java:24)
	at com.dci.intellij.dbn.common.thread.CancellableDatabaseCall.lambda$call$1(CancellableDatabaseCall.java:63)
	at com.dci.intellij.dbn.common.thread.ThreadMonitor.call(ThreadMonitor.java:63)
	at com.dci.intellij.dbn.common.thread.CancellableDatabaseCall.call(CancellableDatabaseCall.java:56)
	at java.base/java.util.concurrent.FutureTask.run(FutureTask.java:264)
	at java.base/java.util.concurrent.ThreadPoolExecutor.runWorker(ThreadPoolExecutor.java:1128)
	at java.base/java.util.concurrent.ThreadPoolExecutor$Worker.run(ThreadPoolExecutor.java:628)
	at com.dci.intellij.dbn.common.thread.ThreadPool.lambda$createThreadFactory$1(ThreadPool.java:39)
	at java.base/java.lang.Thread.run(Thread.java:829)
2022-04-23 20:41:10 jdbc[3]: exception
org.h2.jdbc.JdbcSQLNonTransientException: Savepoint не имеет имени
Savepoint is unnamed [90064-210]
	at org.h2.message.DbException.getJdbcSQLException(DbException.java:573)
	at org.h2.message.DbException.getJdbcSQLException(DbException.java:496)
	at org.h2.message.DbException.get(DbException.java:227)
	at org.h2.message.DbException.get(DbException.java:203)
	at org.h2.message.DbException.get(DbException.java:192)
	at org.h2.jdbc.JdbcSavepoint.getSavepointName(JdbcSavepoint.java:106)
	at com.dci.intellij.dbn.connection.Resources.getSavepointIdentifier(Resources.java:311)
	at com.dci.intellij.dbn.connection.Resources.releaseSavepoint(Resources.java:198)
	at com.dci.intellij.dbn.connection.jdbc.DBNConnection.withSavepoint(DBNConnection.java:413)
	at com.dci.intellij.dbn.connection.Savepoints.call(Savepoints.java:24)
	at com.dci.intellij.dbn.common.thread.CancellableDatabaseCall.lambda$call$1(CancellableDatabaseCall.java:63)
	at com.dci.intellij.dbn.common.thread.ThreadMonitor.call(ThreadMonitor.java:63)
	at com.dci.intellij.dbn.common.thread.CancellableDatabaseCall.call(CancellableDatabaseCall.java:56)
	at java.base/java.util.concurrent.FutureTask.run(FutureTask.java:264)
	at java.base/java.util.concurrent.ThreadPoolExecutor.runWorker(ThreadPoolExecutor.java:1128)
	at java.base/java.util.concurrent.ThreadPoolExecutor$Worker.run(ThreadPoolExecutor.java:628)
	at com.dci.intellij.dbn.common.thread.ThreadPool.lambda$createThreadFactory$1(ThreadPool.java:39)
	at java.base/java.lang.Thread.run(Thread.java:829)
2022-04-23 20:41:13 jdbc[3]: exception
org.h2.jdbc.JdbcSQLNonTransientException: Savepoint не имеет имени
Savepoint is unnamed [90064-210]
	at org.h2.message.DbException.getJdbcSQLException(DbException.java:573)
	at org.h2.message.DbException.getJdbcSQLException(DbException.java:496)
	at org.h2.message.DbException.get(DbException.java:227)
	at org.h2.message.DbException.get(DbException.java:203)
	at org.h2.message.DbException.get(DbException.java:192)
	at org.h2.jdbc.JdbcSavepoint.getSavepointName(JdbcSavepoint.java:106)
	at com.dci.intellij.dbn.connection.Resources.getSavepointIdentifier(Resources.java:311)
	at com.dci.intellij.dbn.connection.Resources.releaseSavepoint(Resources.java:198)
	at com.dci.intellij.dbn.connection.jdbc.DBNConnection.withSavepoint(DBNConnection.java:413)
	at com.dci.intellij.dbn.connection.Savepoints.call(Savepoints.java:24)
	at com.dci.intellij.dbn.common.thread.CancellableDatabaseCall.lambda$call$1(CancellableDatabaseCall.java:63)
	at com.dci.intellij.dbn.common.thread.ThreadMonitor.call(ThreadMonitor.java:63)
	at com.dci.intellij.dbn.common.thread.CancellableDatabaseCall.call(CancellableDatabaseCall.java:56)
	at java.base/java.util.concurrent.FutureTask.run(FutureTask.java:264)
	at java.base/java.util.concurrent.ThreadPoolExecutor.runWorker(ThreadPoolExecutor.java:1128)
	at java.base/java.util.concurrent.ThreadPoolExecutor$Worker.run(ThreadPoolExecutor.java:628)
	at com.dci.intellij.dbn.common.thread.ThreadPool.lambda$createThreadFactory$1(ThreadPool.java:39)
	at java.base/java.lang.Thread.run(Thread.java:829)
2022-04-23 20:55:02 database: flush
org.h2.message.DbException: Внутренняя ошибка: "org.h2.mvstore.MVStoreException: The file is locked: C:/Users/Denis/IdeaProjects/education/Task3/database.mv.db [2.1.210/7]"
General error: "org.h2.mvstore.MVStoreException: The file is locked: C:/Users/Denis/IdeaProjects/education/Task3/database.mv.db [2.1.210/7]" [50000-210]
	at org.h2.message.DbException.get(DbException.java:216)
	at org.h2.message.DbException.convert(DbException.java:414)
	at org.h2.mvstore.db.Store.lambda$new$0(Store.java:120)
	at org.h2.mvstore.MVStore.handleException(MVStore.java:3296)
	at org.h2.mvstore.MVStore.panic(MVStore.java:585)
	at org.h2.mvstore.MVStore.<init>(MVStore.java:461)
	at org.h2.mvstore.MVStore$Builder.open(MVStore.java:4056)
	at org.h2.mvstore.db.Store.<init>(Store.java:129)
	at org.h2.engine.Database.<init>(Database.java:324)
	at org.h2.engine.Engine.openSession(Engine.java:92)
	at org.h2.engine.Engine.openSession(Engine.java:222)
	at org.h2.engine.Engine.createSession(Engine.java:201)
	at org.h2.engine.SessionRemote.connectEmbeddedOrServer(SessionRemote.java:338)
	at org.h2.jdbc.JdbcConnection.<init>(JdbcConnection.java:122)
	at org.h2.Driver.connect(Driver.java:59)
	at java.sql/java.sql.DriverManager.getConnection(DriverManager.java:681)
	at java.sql/java.sql.DriverManager.getConnection(DriverManager.java:229)
	at stage2.Tasks3.DBConnection.getDBConnection(DBConnection.java:11)
	at stage2.Tasks3.App.main(App.java:11)
Caused by: org.h2.jdbc.JdbcSQLNonTransientException: Внутренняя ошибка: "org.h2.mvstore.MVStoreException: The file is locked: C:/Users/Denis/IdeaProjects/education/Task3/database.mv.db [2.1.210/7]"
General error: "org.h2.mvstore.MVStoreException: The file is locked: C:/Users/Denis/IdeaProjects/education/Task3/database.mv.db [2.1.210/7]" [50000-210]
	at org.h2.message.DbException.getJdbcSQLException(DbException.java:573)
	at org.h2.message.DbException.getJdbcSQLException(DbException.java:496)
	... 19 more
Caused by: org.h2.mvstore.MVStoreException: The file is locked: C:/Users/Denis/IdeaProjects/education/Task3/database.mv.db [2.1.210/7]
	at org.h2.mvstore.DataUtils.newMVStoreException(DataUtils.java:1004)
	at org.h2.mvstore.FileStore.open(FileStore.java:163)
	at org.h2.mvstore.MVStore.<init>(MVStore.java:444)
	... 13 more
2022-04-23 20:55:25 jdbc[3]: exception
org.h2.jdbc.JdbcSQLSyntaxErrorException: Синтаксическая ошибка в выражении SQL "insert into MAZE\000a(LENGTH)\000a[*]OUTPUT\000avalues (10);"; ожидалось "OVERRIDING, DIRECT, SORTED, DEFAULT, VALUES, SET, WITH, (, SELECT, TABLE, VALUES"
Syntax error in SQL statement "insert into MAZE\000a(LENGTH)\000a[*]OUTPUT\000avalues (10);"; expected "OVERRIDING, DIRECT, SORTED, DEFAULT, VALUES, SET, WITH, (, SELECT, TABLE, VALUES"; SQL statement:
insert into MAZE
(LENGTH)
OUTPUT
values (10); [42001-210]
2022-04-23 20:56:02 jdbc[3]: exception
org.h2.jdbc.JdbcSQLNonTransientException: Данный метод не разрешен для PreparedStatement; используйте Statement.
This method is not allowed for a prepared statement; use a regular statement instead. [90130-210]
	at org.h2.message.DbException.getJdbcSQLException(DbException.java:573)
	at org.h2.message.DbException.getJdbcSQLException(DbException.java:496)
	at org.h2.message.DbException.get(DbException.java:227)
	at org.h2.message.DbException.get(DbException.java:203)
	at org.h2.message.DbException.get(DbException.java:192)
	at org.h2.jdbc.JdbcStatement.executeInternal(JdbcStatement.java:231)
	at org.h2.jdbc.JdbcStatement.execute(JdbcStatement.java:223)
	at stage2.Tasks3.Inquire.createMaze(Inquire.java:14)
	at stage2.Tasks3.App.main(App.java:15)
2022-04-23 21:15:03 jdbc[3]: exception
org.h2.jdbc.JdbcSQLSyntaxErrorException: Неверное количество столбцов
Column count does not match; SQL statement:
insert into CELL
(CELL_VALUE,X,Y)
values (' ',0,0,3); [21002-210]
	at org.h2.message.DbException.getJdbcSQLException(DbException.java:521)
	at org.h2.message.DbException.getJdbcSQLException(DbException.java:496)
	at org.h2.message.DbException.get(DbException.java:227)
	at org.h2.message.DbException.get(DbException.java:203)
	at org.h2.message.DbException.get(DbException.java:192)
	at org.h2.command.dml.Insert.prepare(Insert.java:295)
	at org.h2.command.Parser.prepareCommand(Parser.java:557)
	at org.h2.engine.SessionLocal.prepareLocal(SessionLocal.java:615)
	at org.h2.engine.SessionLocal.prepareCommand(SessionLocal.java:553)
	at org.h2.jdbc.JdbcConnection.prepareCommand(JdbcConnection.java:1116)
	at org.h2.jdbc.JdbcStatement.executeInternal(JdbcStatement.java:237)
	at org.h2.jdbc.JdbcStatement.execute(JdbcStatement.java:223)
	at stage2.Tasks3.Inquire.createCell(Inquire.java:31)
	at stage2.Tasks3.App.main(App.java:18)
2022-04-23 21:15:29 jdbc[3]: exception
org.h2.jdbc.JdbcSQLNonTransientException: Savepoint не имеет имени
Savepoint is unnamed [90064-210]
	at org.h2.message.DbException.getJdbcSQLException(DbException.java:573)
	at org.h2.message.DbException.getJdbcSQLException(DbException.java:496)
	at org.h2.message.DbException.get(DbException.java:227)
	at org.h2.message.DbException.get(DbException.java:203)
	at org.h2.message.DbException.get(DbException.java:192)
	at org.h2.jdbc.JdbcSavepoint.getSavepointName(JdbcSavepoint.java:106)
	at com.dci.intellij.dbn.connection.Resources.getSavepointIdentifier(Resources.java:311)
	at com.dci.intellij.dbn.connection.Resources.releaseSavepoint(Resources.java:198)
	at com.dci.intellij.dbn.connection.jdbc.DBNConnection.withSavepoint(DBNConnection.java:413)
	at com.dci.intellij.dbn.connection.Savepoints.call(Savepoints.java:24)
	at com.dci.intellij.dbn.common.thread.CancellableDatabaseCall.lambda$call$1(CancellableDatabaseCall.java:63)
	at com.dci.intellij.dbn.common.thread.ThreadMonitor.call(ThreadMonitor.java:63)
	at com.dci.intellij.dbn.common.thread.CancellableDatabaseCall.call(CancellableDatabaseCall.java:56)
	at java.base/java.util.concurrent.FutureTask.run(FutureTask.java:264)
	at java.base/java.util.concurrent.ThreadPoolExecutor.runWorker(ThreadPoolExecutor.java:1128)
	at java.base/java.util.concurrent.ThreadPoolExecutor$Worker.run(ThreadPoolExecutor.java:628)
	at com.dci.intellij.dbn.common.thread.ThreadPool.lambda$createThreadFactory$1(ThreadPool.java:39)
	at java.base/java.lang.Thread.run(Thread.java:829)
2022-04-23 21:16:03 jdbc[3]: exception
org.h2.jdbc.JdbcSQLNonTransientException: Savepoint не имеет имени
Savepoint is unnamed [90064-210]
	at org.h2.message.DbException.getJdbcSQLException(DbException.java:573)
	at org.h2.message.DbException.getJdbcSQLException(DbException.java:496)
	at org.h2.message.DbException.get(DbException.java:227)
	at org.h2.message.DbException.get(DbException.java:203)
	at org.h2.message.DbException.get(DbException.java:192)
	at org.h2.jdbc.JdbcSavepoint.getSavepointName(JdbcSavepoint.java:106)
	at com.dci.intellij.dbn.connection.Resources.getSavepointIdentifier(Resources.java:311)
	at com.dci.intellij.dbn.connection.Resources.releaseSavepoint(Resources.java:198)
	at com.dci.intellij.dbn.connection.jdbc.DBNConnection.withSavepoint(DBNConnection.java:413)
	at com.dci.intellij.dbn.connection.Savepoints.call(Savepoints.java:24)
	at com.dci.intellij.dbn.common.thread.CancellableDatabaseCall.lambda$call$1(CancellableDatabaseCall.java:63)
	at com.dci.intellij.dbn.common.thread.ThreadMonitor.call(ThreadMonitor.java:63)
	at com.dci.intellij.dbn.common.thread.CancellableDatabaseCall.call(CancellableDatabaseCall.java:56)
	at java.base/java.util.concurrent.FutureTask.run(FutureTask.java:264)
	at java.base/java.util.concurrent.ThreadPoolExecutor.runWorker(ThreadPoolExecutor.java:1128)
	at java.base/java.util.concurrent.ThreadPoolExecutor$Worker.run(ThreadPoolExecutor.java:628)
	at com.dci.intellij.dbn.common.thread.ThreadPool.lambda$createThreadFactory$1(ThreadPool.java:39)
	at java.base/java.lang.Thread.run(Thread.java:829)
2022-04-23 21:16:10 jdbc[3]: exception
org.h2.jdbc.JdbcSQLNonTransientException: Savepoint не имеет имени
Savepoint is unnamed [90064-210]
	at org.h2.message.DbException.getJdbcSQLException(DbException.java:573)
	at org.h2.message.DbException.getJdbcSQLException(DbException.java:496)
	at org.h2.message.DbException.get(DbException.java:227)
	at org.h2.message.DbException.get(DbException.java:203)
	at org.h2.message.DbException.get(DbException.java:192)
	at org.h2.jdbc.JdbcSavepoint.getSavepointName(JdbcSavepoint.java:106)
	at com.dci.intellij.dbn.connection.Resources.getSavepointIdentifier(Resources.java:311)
	at com.dci.intellij.dbn.connection.Resources.releaseSavepoint(Resources.java:198)
	at com.dci.intellij.dbn.connection.jdbc.DBNConnection.withSavepoint(DBNConnection.java:413)
	at com.dci.intellij.dbn.connection.Savepoints.call(Savepoints.java:24)
	at com.dci.intellij.dbn.common.thread.CancellableDatabaseCall.lambda$call$1(CancellableDatabaseCall.java:63)
	at com.dci.intellij.dbn.common.thread.ThreadMonitor.call(ThreadMonitor.java:63)
	at com.dci.intellij.dbn.common.thread.CancellableDatabaseCall.call(CancellableDatabaseCall.java:56)
	at java.base/java.util.concurrent.FutureTask.run(FutureTask.java:264)
	at java.base/java.util.concurrent.ThreadPoolExecutor.runWorker(ThreadPoolExecutor.java:1128)
	at java.base/java.util.concurrent.ThreadPoolExecutor$Worker.run(ThreadPoolExecutor.java:628)
	at com.dci.intellij.dbn.common.thread.ThreadPool.lambda$createThreadFactory$1(ThreadPool.java:39)
	at java.base/java.lang.Thread.run(Thread.java:829)
2022-04-23 21:16:13 jdbc[3]: exception
org.h2.jdbc.JdbcSQLNonTransientException: Savepoint не имеет имени
Savepoint is unnamed [90064-210]
	at org.h2.message.DbException.getJdbcSQLException(DbException.java:573)
	at org.h2.message.DbException.getJdbcSQLException(DbException.java:496)
	at org.h2.message.DbException.get(DbException.java:227)
	at org.h2.message.DbException.get(DbException.java:203)
	at org.h2.message.DbException.get(DbException.java:192)
	at org.h2.jdbc.JdbcSavepoint.getSavepointName(JdbcSavepoint.java:106)
	at com.dci.intellij.dbn.connection.Resources.getSavepointIdentifier(Resources.java:311)
	at com.dci.intellij.dbn.connection.Resources.releaseSavepoint(Resources.java:198)
	at com.dci.intellij.dbn.connection.jdbc.DBNConnection.withSavepoint(DBNConnection.java:413)
	at com.dci.intellij.dbn.connection.Savepoints.call(Savepoints.java:24)
	at com.dci.intellij.dbn.common.thread.CancellableDatabaseCall.lambda$call$1(CancellableDatabaseCall.java:63)
	at com.dci.intellij.dbn.common.thread.ThreadMonitor.call(ThreadMonitor.java:63)
	at com.dci.intellij.dbn.common.thread.CancellableDatabaseCall.call(CancellableDatabaseCall.java:56)
	at java.base/java.util.concurrent.FutureTask.run(FutureTask.java:264)
	at java.base/java.util.concurrent.ThreadPoolExecutor.runWorker(ThreadPoolExecutor.java:1128)
	at java.base/java.util.concurrent.ThreadPoolExecutor$Worker.run(ThreadPoolExecutor.java:628)
	at com.dci.intellij.dbn.common.thread.ThreadPool.lambda$createThreadFactory$1(ThreadPool.java:39)
	at java.base/java.lang.Thread.run(Thread.java:829)
2022-04-23 21:19:53 jdbc[3]: exception
org.h2.jdbc.JdbcSQLNonTransientException: Savepoint не имеет имени
Savepoint is unnamed [90064-210]
	at org.h2.message.DbException.getJdbcSQLException(DbException.java:573)
	at org.h2.message.DbException.getJdbcSQLException(DbException.java:496)
	at org.h2.message.DbException.get(DbException.java:227)
	at org.h2.message.DbException.get(DbException.java:203)
	at org.h2.message.DbException.get(DbException.java:192)
	at org.h2.jdbc.JdbcSavepoint.getSavepointName(JdbcSavepoint.java:106)
	at com.dci.intellij.dbn.connection.Resources.getSavepointIdentifier(Resources.java:311)
	at com.dci.intellij.dbn.connection.Resources.releaseSavepoint(Resources.java:198)
	at com.dci.intellij.dbn.connection.jdbc.DBNConnection.withSavepoint(DBNConnection.java:413)
	at com.dci.intellij.dbn.connection.Savepoints.call(Savepoints.java:24)
	at com.dci.intellij.dbn.common.thread.CancellableDatabaseCall.lambda$call$1(CancellableDatabaseCall.java:63)
	at com.dci.intellij.dbn.common.thread.ThreadMonitor.call(ThreadMonitor.java:63)
	at com.dci.intellij.dbn.common.thread.CancellableDatabaseCall.call(CancellableDatabaseCall.java:56)
	at java.base/java.util.concurrent.FutureTask.run(FutureTask.java:264)
	at java.base/java.util.concurrent.ThreadPoolExecutor.runWorker(ThreadPoolExecutor.java:1128)
	at java.base/java.util.concurrent.ThreadPoolExecutor$Worker.run(ThreadPoolExecutor.java:628)
	at com.dci.intellij.dbn.common.thread.ThreadPool.lambda$createThreadFactory$1(ThreadPool.java:39)
	at java.base/java.lang.Thread.run(Thread.java:829)
2022-04-23 21:22:17 jdbc[3]: exception
org.h2.jdbc.JdbcSQLSyntaxErrorException: Неоднозначное имя столбца "ID_MAZE"
Ambiguous column name "ID_MAZE"; SQL statement:
select LENGTH, CELL.CELL_VALUE,CELL.X,CELL.Y from MAZE INNER JOIN CELL ON CELL.ID_MAZE=MAZE.ID_MAZE WHERE ID_MAZE=4 [90059-210]
	at org.h2.message.DbException.getJdbcSQLException(DbException.java:651)
	at org.h2.message.DbException.getJdbcSQLException(DbException.java:496)
	at org.h2.message.DbException.get(DbException.java:227)
	at org.h2.message.DbException.get(DbException.java:203)
	at org.h2.expression.ExpressionColumn.mapColumn(ExpressionColumn.java:197)
	at org.h2.expression.ExpressionColumn.mapColumns(ExpressionColumn.java:175)
	at org.h2.expression.condition.Comparison.mapColumns(Comparison.java:474)
	at org.h2.expression.condition.ConditionAndOr.mapColumns(ConditionAndOr.java:289)
	at org.h2.command.query.Select.mapColumns(Select.java:1549)
	at org.h2.command.query.Select.init(Select.java:1100)
	at org.h2.command.Parser.parseQuery(Parser.java:2583)
	at org.h2.command.Parser.parsePrepared(Parser.java:707)
	at org.h2.command.Parser.parse(Parser.java:674)
	at org.h2.command.Parser.parse(Parser.java:644)
	at org.h2.command.Parser.prepareCommand(Parser.java:551)
	at org.h2.engine.SessionLocal.prepareLocal(SessionLocal.java:615)
	at org.h2.engine.SessionLocal.prepareCommand(SessionLocal.java:553)
	at org.h2.jdbc.JdbcConnection.prepareCommand(JdbcConnection.java:1116)
	at org.h2.jdbc.JdbcStatement.executeQuery(JdbcStatement.java:92)
	at stage2.Tasks3.Inquire.printMazeById(Inquire.java:48)
	at stage2.Tasks3.App.main(App.java:13)
2022-04-23 21:22:55 jdbc[3]: exception
org.h2.jdbc.JdbcSQLSyntaxErrorException: Столбец "ID_CELL" не найден
Column "ID_CELL" not found [42122-210]
	at org.h2.message.DbException.getJdbcSQLException(DbException.java:521)
	at org.h2.message.DbException.getJdbcSQLException(DbException.java:496)
	at org.h2.message.DbException.get(DbException.java:227)
	at org.h2.message.DbException.get(DbException.java:203)
	at org.h2.jdbc.JdbcResultSet.getColumnIndex(JdbcResultSet.java:3492)
	at org.h2.jdbc.JdbcResultSet.getInt(JdbcResultSet.java:337)
	at stage2.Tasks3.Inquire.printMazeById(Inquire.java:52)
	at stage2.Tasks3.App.main(App.java:13)
2022-04-23 21:45:01 jdbc[3]: exception
org.h2.jdbc.JdbcSQLNonTransientException: Savepoint не имеет имени
Savepoint is unnamed [90064-210]
	at org.h2.message.DbException.getJdbcSQLException(DbException.java:573)
	at org.h2.message.DbException.getJdbcSQLException(DbException.java:496)
	at org.h2.message.DbException.get(DbException.java:227)
	at org.h2.message.DbException.get(DbException.java:203)
	at org.h2.message.DbException.get(DbException.java:192)
	at org.h2.jdbc.JdbcSavepoint.getSavepointName(JdbcSavepoint.java:106)
	at com.dci.intellij.dbn.connection.Resources.getSavepointIdentifier(Resources.java:311)
	at com.dci.intellij.dbn.connection.Resources.releaseSavepoint(Resources.java:198)
	at com.dci.intellij.dbn.connection.jdbc.DBNConnection.withSavepoint(DBNConnection.java:413)
	at com.dci.intellij.dbn.connection.Savepoints.call(Savepoints.java:24)
	at com.dci.intellij.dbn.common.thread.CancellableDatabaseCall.lambda$call$1(CancellableDatabaseCall.java:63)
	at com.dci.intellij.dbn.common.thread.ThreadMonitor.call(ThreadMonitor.java:63)
	at com.dci.intellij.dbn.common.thread.CancellableDatabaseCall.call(CancellableDatabaseCall.java:56)
	at java.base/java.util.concurrent.FutureTask.run(FutureTask.java:264)
	at java.base/java.util.concurrent.ThreadPoolExecutor.runWorker(ThreadPoolExecutor.java:1128)
	at java.base/java.util.concurrent.ThreadPoolExecutor$Worker.run(ThreadPoolExecutor.java:628)
	at com.dci.intellij.dbn.common.thread.ThreadPool.lambda$createThreadFactory$1(ThreadPool.java:39)
	at java.base/java.lang.Thread.run(Thread.java:829)
2022-04-23 21:48:53 jdbc[3]: exception
org.h2.jdbc.JdbcSQLSyntaxErrorException: Столбец "ID_CELL" не найден
Column "ID_CELL" not found; SQL statement:
ALTER TABLE MAZE ALTER COLUMN ID_CELL RESTART WITH 1 [42122-210]
	at org.h2.message.DbException.getJdbcSQLException(DbException.java:521)
	at org.h2.message.DbException.getJdbcSQLException(DbException.java:496)
	at org.h2.message.DbException.get(DbException.java:227)
	at org.h2.message.DbException.get(DbException.java:203)
	at org.h2.table.Table.getColumn(Table.java:770)
	at org.h2.command.Parser.columnIfTableExists(Parser.java:8941)
	at org.h2.command.Parser.parseAlterTableAlter(Parser.java:8517)
	at org.h2.command.Parser.parseAlterTable(Parser.java:8503)
	at org.h2.command.Parser.parseAlter(Parser.java:7556)
	at org.h2.command.Parser.parsePrepared(Parser.java:730)
	at org.h2.command.Parser.parse(Parser.java:674)
	at org.h2.command.Parser.parse(Parser.java:644)
	at org.h2.command.Parser.prepareCommand(Parser.java:551)
	at org.h2.engine.SessionLocal.prepareLocal(SessionLocal.java:615)
	at org.h2.engine.SessionLocal.prepareCommand(SessionLocal.java:553)
	at org.h2.jdbc.JdbcConnection.prepareCommand(JdbcConnection.java:1116)
	at org.h2.jdbc.JdbcStatement.executeInternal(JdbcStatement.java:237)
	at org.h2.jdbc.JdbcStatement.execute(JdbcStatement.java:223)
	at com.dci.intellij.dbn.connection.jdbc.DBNStatement.lambda$execute$0(DBNStatement.java:139)
	at com.dci.intellij.dbn.connection.jdbc.DBNStatement.managed(DBNStatement.java:121)
	at com.dci.intellij.dbn.connection.jdbc.DBNStatement.execute(DBNStatement.java:139)
	at com.dci.intellij.dbn.execution.statement.processor.StatementExecutionBasicProcessor$1.execute(StatementExecutionBasicProcessor.java:438)
	at com.dci.intellij.dbn.execution.statement.processor.StatementExecutionBasicProcessor$1.execute(StatementExecutionBasicProcessor.java:434)
	at com.dci.intellij.dbn.common.thread.CancellableDatabaseCall.lambda$call$0(CancellableDatabaseCall.java:65)
	at com.dci.intellij.dbn.connection.jdbc.DBNConnection.withSavepoint(DBNConnection.java:408)
	at com.dci.intellij.dbn.connection.Savepoints.call(Savepoints.java:24)
	at com.dci.intellij.dbn.common.thread.CancellableDatabaseCall.lambda$call$1(CancellableDatabaseCall.java:63)
	at com.dci.intellij.dbn.common.thread.ThreadMonitor.call(ThreadMonitor.java:63)
	at com.dci.intellij.dbn.common.thread.CancellableDatabaseCall.call(CancellableDatabaseCall.java:56)
	at java.base/java.util.concurrent.FutureTask.run(FutureTask.java:264)
	at java.base/java.util.concurrent.ThreadPoolExecutor.runWorker(ThreadPoolExecutor.java:1128)
	at java.base/java.util.concurrent.ThreadPoolExecutor$Worker.run(ThreadPoolExecutor.java:628)
	at com.dci.intellij.dbn.common.thread.ThreadPool.lambda$createThreadFactory$1(ThreadPool.java:39)
	at java.base/java.lang.Thread.run(Thread.java:829)
2022-04-23 21:48:53 jdbc[3]: exception
org.h2.jdbc.JdbcSQLNonTransientException: Savepoint не имеет имени
Savepoint is unnamed [90064-210]
	at org.h2.message.DbException.getJdbcSQLException(DbException.java:573)
	at org.h2.message.DbException.getJdbcSQLException(DbException.java:496)
	at org.h2.message.DbException.get(DbException.java:227)
	at org.h2.message.DbException.get(DbException.java:203)
	at org.h2.message.DbException.get(DbException.java:192)
	at org.h2.jdbc.JdbcSavepoint.getSavepointName(JdbcSavepoint.java:106)
	at com.dci.intellij.dbn.connection.Resources.getSavepointIdentifier(Resources.java:311)
	at com.dci.intellij.dbn.connection.Resources.rollback(Resources.java:151)
	at com.dci.intellij.dbn.connection.Resources.lambda$rollbackSilently$22(Resources.java:145)
	at com.dci.intellij.dbn.common.util.Unsafe.silent(Unsafe.java:18)
	at com.dci.intellij.dbn.connection.Resources.rollbackSilently(Resources.java:145)
	at com.dci.intellij.dbn.connection.jdbc.DBNConnection.withSavepoint(DBNConnection.java:410)
	at com.dci.intellij.dbn.connection.Savepoints.call(Savepoints.java:24)
	at com.dci.intellij.dbn.common.thread.CancellableDatabaseCall.lambda$call$1(CancellableDatabaseCall.java:63)
	at com.dci.intellij.dbn.common.thread.ThreadMonitor.call(ThreadMonitor.java:63)
	at com.dci.intellij.dbn.common.thread.CancellableDatabaseCall.call(CancellableDatabaseCall.java:56)
	at java.base/java.util.concurrent.FutureTask.run(FutureTask.java:264)
	at java.base/java.util.concurrent.ThreadPoolExecutor.runWorker(ThreadPoolExecutor.java:1128)
	at java.base/java.util.concurrent.ThreadPoolExecutor$Worker.run(ThreadPoolExecutor.java:628)
	at com.dci.intellij.dbn.common.thread.ThreadPool.lambda$createThreadFactory$1(ThreadPool.java:39)
	at java.base/java.lang.Thread.run(Thread.java:829)
2022-04-23 21:48:53 jdbc[3]: exception
org.h2.jdbc.JdbcSQLNonTransientException: Savepoint не имеет имени
Savepoint is unnamed [90064-210]
	at org.h2.message.DbException.getJdbcSQLException(DbException.java:573)
	at org.h2.message.DbException.getJdbcSQLException(DbException.java:496)
	at org.h2.message.DbException.get(DbException.java:227)
	at org.h2.message.DbException.get(DbException.java:203)
	at org.h2.message.DbException.get(DbException.java:192)
	at org.h2.jdbc.JdbcSavepoint.getSavepointName(JdbcSavepoint.java:106)
	at com.dci.intellij.dbn.connection.Resources.getSavepointIdentifier(Resources.java:311)
	at com.dci.intellij.dbn.connection.Resources.releaseSavepoint(Resources.java:198)
	at com.dci.intellij.dbn.connection.jdbc.DBNConnection.withSavepoint(DBNConnection.java:413)
	at com.dci.intellij.dbn.connection.Savepoints.call(Savepoints.java:24)
	at com.dci.intellij.dbn.common.thread.CancellableDatabaseCall.lambda$call$1(CancellableDatabaseCall.java:63)
	at com.dci.intellij.dbn.common.thread.ThreadMonitor.call(ThreadMonitor.java:63)
	at com.dci.intellij.dbn.common.thread.CancellableDatabaseCall.call(CancellableDatabaseCall.java:56)
	at java.base/java.util.concurrent.FutureTask.run(FutureTask.java:264)
	at java.base/java.util.concurrent.ThreadPoolExecutor.runWorker(ThreadPoolExecutor.java:1128)
	at java.base/java.util.concurrent.ThreadPoolExecutor$Worker.run(ThreadPoolExecutor.java:628)
	at com.dci.intellij.dbn.common.thread.ThreadPool.lambda$createThreadFactory$1(ThreadPool.java:39)
	at java.base/java.lang.Thread.run(Thread.java:829)
2022-04-23 21:48:53 jdbc[3]: exception
org.h2.jdbc.JdbcSQLNonTransientException: Объект уже закрыт
The object is already closed [90007-210]
2022-04-23 21:49:06 jdbc[3]: exception
org.h2.jdbc.JdbcSQLNonTransientException: Savepoint не имеет имени
Savepoint is unnamed [90064-210]
	at org.h2.message.DbException.getJdbcSQLException(DbException.java:573)
	at org.h2.message.DbException.getJdbcSQLException(DbException.java:496)
	at org.h2.message.DbException.get(DbException.java:227)
	at org.h2.message.DbException.get(DbException.java:203)
	at org.h2.message.DbException.get(DbException.java:192)
	at org.h2.jdbc.JdbcSavepoint.getSavepointName(JdbcSavepoint.java:106)
	at com.dci.intellij.dbn.connection.Resources.getSavepointIdentifier(Resources.java:311)
	at com.dci.intellij.dbn.connection.Resources.releaseSavepoint(Resources.java:198)
	at com.dci.intellij.dbn.connection.jdbc.DBNConnection.withSavepoint(DBNConnection.java:413)
	at com.dci.intellij.dbn.connection.Savepoints.call(Savepoints.java:24)
	at com.dci.intellij.dbn.common.thread.CancellableDatabaseCall.lambda$call$1(CancellableDatabaseCall.java:63)
	at com.dci.intellij.dbn.common.thread.ThreadMonitor.call(ThreadMonitor.java:63)
	at com.dci.intellij.dbn.common.thread.CancellableDatabaseCall.call(CancellableDatabaseCall.java:56)
	at java.base/java.util.concurrent.FutureTask.run(FutureTask.java:264)
	at java.base/java.util.concurrent.ThreadPoolExecutor.runWorker(ThreadPoolExecutor.java:1128)
	at java.base/java.util.concurrent.ThreadPoolExecutor$Worker.run(ThreadPoolExecutor.java:628)
	at com.dci.intellij.dbn.common.thread.ThreadPool.lambda$createThreadFactory$1(ThreadPool.java:39)
	at java.base/java.lang.Thread.run(Thread.java:829)
2022-04-23 21:49:12 jdbc[3]: exception
org.h2.jdbc.JdbcSQLNonTransientException: Savepoint не имеет имени
Savepoint is unnamed [90064-210]
	at org.h2.message.DbException.getJdbcSQLException(DbException.java:573)
	at org.h2.message.DbException.getJdbcSQLException(DbException.java:496)
	at org.h2.message.DbException.get(DbException.java:227)
	at org.h2.message.DbException.get(DbException.java:203)
	at org.h2.message.DbException.get(DbException.java:192)
	at org.h2.jdbc.JdbcSavepoint.getSavepointName(JdbcSavepoint.java:106)
	at com.dci.intellij.dbn.connection.Resources.getSavepointIdentifier(Resources.java:311)
	at com.dci.intellij.dbn.connection.Resources.releaseSavepoint(Resources.java:198)
	at com.dci.intellij.dbn.connection.jdbc.DBNConnection.withSavepoint(DBNConnection.java:413)
	at com.dci.intellij.dbn.connection.Savepoints.call(Savepoints.java:24)
	at com.dci.intellij.dbn.common.thread.CancellableDatabaseCall.lambda$call$1(CancellableDatabaseCall.java:63)
	at com.dci.intellij.dbn.common.thread.ThreadMonitor.call(ThreadMonitor.java:63)
	at com.dci.intellij.dbn.common.thread.CancellableDatabaseCall.call(CancellableDatabaseCall.java:56)
	at java.base/java.util.concurrent.FutureTask.run(FutureTask.java:264)
	at java.base/java.util.concurrent.ThreadPoolExecutor.runWorker(ThreadPoolExecutor.java:1128)
	at java.base/java.util.concurrent.ThreadPoolExecutor$Worker.run(ThreadPoolExecutor.java:628)
	at com.dci.intellij.dbn.common.thread.ThreadPool.lambda$createThreadFactory$1(ThreadPool.java:39)
	at java.base/java.lang.Thread.run(Thread.java:829)
